Workbook
Name ___B140007: [1]건축!#REF!
Name ___B140007: [1]건축!#REF!
Name ___B140007: [1]건축!#REF!
Name ___B140007: #REF!
Name __B140007: [1]건축!#REF!
Name __B140007: [1]건축!#REF!
Name __B140007: [1]건축!#REF!
Name __B140007: #REF!
Name _1: #N/A
Name _2: #N/A
Name _3: #REF!
Name _3: #REF!
Name _3: #REF!
Name _3: #REF!
Name _3: #REF!
Name _3: #REF!
Name _B140007: [1]건축!#REF!
Name _B140007: [1]건축!#REF!
Name _B140007: [1]건축!#REF!
Name _B140007: #REF!
Name _B140007: #REF!
Name \a: #N/A
Name \z: #N/A
Name A: #N/A
Name AA: #REF!
Name AA: #REF!
Name AA: #REF!
Name CODE: #REF!
Name CODE: #REF!
Name CODE: #REF!
Name CODE: #REF!
Name CODE: #REF!
Name DATA: #REF!
Name DATA: #REF!
Name DATA: #REF!
Name DATA: #REF!
Name DATA: #REF!
Name DEMO: #REF!
Name DEMO: #REF!
Name DEMO: #REF!
Name DEMO: #REF!
Name DEMO: #REF!
Name DEMO: #REF!
Name T: #N/A
Name UNIT: #REF!
Name UNIT: #REF!
Name UNIT: #REF!
Name UNIT: #REF!
Name UNIT: #REF!
Name WW: #REF!
Name WW: #REF!
Name WW: #REF!
Name 經費: #REF!
Name 經費: #REF!
Name 經費: #REF!
Name 經費: #REF!
Name 經費: #REF!
Name 기: #REF!
Name 기: [18]경산!#REF!
Name 기: [18]경산!#REF!

Sheet ECSYSTEM

Sheet 표지
A4: =갑지!AE12 -> 파주시 운정 자동집하시설 운영비용 원가산정용역
B6: 설계내역서
B12: 2023. 07.
D17: 파 주 시
D18: 환경시설과

Sheet 설명서
A1: 설 계 설 명 서
B5: 1.사업명: | C5: =갑지!AE12 -> 파주시 운정 자동집하시설 운영비용 원가산정용역
B8: 2.사업위치: | C8: =갑지!AE10 -> 파주시 운정신도시 집하장(가람집하장, 산내집하장, 한울집하장, 한빛집하장)
B11: 3.사업목적: | C11: 파주시 운정신도시 자동집하시설을 운영관리함으로서 생활폐기물을 안정적으로 처리하는데 그 목적이 있음.
B15: 4.사업개요: | C15: =갑지!AE12 -> 파주시 운정 자동집하시설 운영비용 원가산정용역
B20: 5.과업수행방법: | C20: 과업지시서에 준함.
B22: 6.총용역기간: | C22: 2023년 2월 15일 ~ 2023년 07월14일(3년)
B24: -1차계약분: | C24: 2024년 1월 1일 ~ 2024년 12월 31일(12개월)
B25: -2차계약분: | C25: 2025년 1월 1일 ~ 2025년 12월 31일(12개월)
B26: -3차계약분: | C26: 2026년 1월 1일 ~ 2026년 12월 31일(12개월)

Sheet 36개월총괄
A1: <총괄원가내역서>
A2: 사업명 : 파주시 운정신도시 생활폐기물 자동집하시설 운영관리 용역(총괄) | K2: 단위 : 원/년
E3: 구 분 | G3: 합 계 | H3: 2024년(1차분) | I3: 2025년(2차분) | J3: 2026년(3차분) | K3: 비 고
A4: 비 목 | G4: 금 액 | H4: 금 액 | I4: 금 액 | J4: 금 액
A5: 고 정 비 | B5: 인 건 비 | C5: 기 본 급 | G5: =SUM(H5:J5) -> 2050385724 | H5: ='용역원가(24년)'!H7 -> 683461908 | I5: =H5 -> 683461908 | J5: =I5 -> 683461908
C6: 제수당 | E6: 년차수당 | G6: =SUM(H6:J6) -> 157111200 | H6: ='용역원가(24년)'!H8 -> 52370400 | I6: =H6 -> 52370400 | J6: =I6 -> 52370400
D7: 연장근로수당 | G7: =SUM(H7:J7) -> 0 | H7: ='용역원가(24년)'!H9 -> 0 | I7: =H7 -> 0 | J7: =I7 -> 0
D8: 휴일근로수당 | G8: =SUM(H8:J8) -> 320619600 | H8: ='용역원가(24년)'!H10 -> 106873200 | I8: =H8 -> 106873200 | J8: =I8 -> 106873200
E9: 소계 | G9: =SUM(H9:J9) -> 477730800 | H9: ='용역원가(24년)'!H11 -> 159243600 | I9: =H9 -> 159243600 | J9: =I9 -> 159243600
C10: 상여금 | G10: =SUM(H10:J10) -> 683461692 | H10: ='용역원가(24년)'!H12 -> 227820564 | I10: =H10 -> 227820564 | J10: =I10 -> 227820564
C11: 퇴직급여충당금 | G11: =SUM(H11:J11) -> 267631056 | H11: ='용역원가(24년)'!H13 -> 89210352 | I11: =H11 -> 89210352 | J11: =I11 -> 89210352
C12: 계 | G12: =SUM(H12:J12) -> 3479209272 | H12: ='용역원가(24년)'!H14 -> 1159736424 | I12: =H12 -> 1159736424 | J12: =I12 -> 1159736424
B13: 고 정 경 비 | C13: 보 험 료 | E13: 산재보험료 | G13: =SUM(H13:J13) -> 28903752 | H13: ='용역원가(24년)'!H15 -> 9634584 | I13: =H13 -> 9634584 | J13: =I13 -> 9634584
E14: 국민연금 | G14: =SUM(H14:J14) -> 144520416 | H14: ='용역원가(24년)'!H16 -> 48173472 | I14: =H14 -> 48173472 | J14: =I14 -> 48173472
E15: 고용보험료 | G15: =SUM(H15:J15) -> 36932508 | H15: ='용역원가(24년)'!H17 -> 12310836 | I15: =H15 -> 12310836 | J15: =I15 -> 12310836
E16: 국민건강보험료 | G16: =SUM(H16:J16) -> 113850036 | H16: ='용역원가(24년)'!H18 -> 37950012 | I16: =H16 -> 37950012 | J16: =I16 -> 37950012
E17: 노인장기요양보험료 | G17: =SUM(H17:J17) -> 14583924 | H17: ='용역원가(24년)'!H19 -> 4861308 | I17: =H17 -> 4861308 | J17: =I17 -> 4861308
E18: 임금채권보장보험료 | G18: =SUM(H18:J18) -> 1926396 | H18: ='용역원가(24년)'!H20 -> 642132 | I18: =H18 -> 642132 | J18: =I18 -> 642132
E19: 석면피해구제분담금 | G19: =SUM(H19:J19) -> 127944 | H19: ='용역원가(24년)'!H21 -> 42648 | I19: =H19 -> 42648 | J19: =I19 -> 42648
C20: 복리후생비 | G20: =SUM(H20:J20) -> 175292712 | H20: ='용역원가(24년)'!H22 -> 58430904 | I20: =H20 -> 58430904 | J20: =I20 -> 58430904
C21: 안전관리비 | G21: =SUM(H21:J21) -> 64713291 | H21: ='용역원가(24년)'!H23 -> 21571097 | I21: =H21 -> 21571097 | J21: =I21 -> 21571097
C22: 교육훈련비 | G22: =SUM(H22:J22) -> 6026292 | H22: ='용역원가(24년)'!H24 -> 2008764 | I22: =H22 -> 2008764 | J22: =I22 -> 2008764
C23: 소모품비 | G23: =SUM(H23:J23) -> 22587624 | H23: ='용역원가(24년)'!H25 -> 7529208 | I23: =H23 -> 7529208 | J23: =I23 -> 7529208
C24: 출장여비 | G24: =SUM(H24:J24) -> 3443796 | H24: ='용역원가(24년)'!H26 -> 1147932 | I24: =H24 -> 1147932 | J24: =I24 -> 1147932
C25: 통신 및 우편비 | G25: =SUM(H25:J25) -> 6230376 | H25: ='용역원가(24년)'!H27 -> 2076792 | I25: =H25 -> 2076792 | J25: =I25 -> 2076792
C26: 계 | G26: =SUM(H26:J26) -> 619139067 | H26: ='용역원가(24년)'!H28 -> 206379689 | I26: =H26 -> 206379689 | J26: =I26 -> 206379689
B27: 순용역원가 | G27: =SUM(H27:J27) -> 4098348339 | H27: ='용역원가(24년)'!H29 -> 1366116113 | I27: =H27 -> 1366116113 | J27: =I27 -> 1366116113
B28: 일반관리비(9%) | G28: =SUM(H28:J28) -> 368851320 | H28: ='용역원가(24년)'!H30 -> 122950440 | I28: =H28 -> 122950440 | J28: =I28 -> 122950440
B29: 이윤(10%) | G29: =SUM(H29:J29) -> 446719932 | H29: ='용역원가(24년)'!H31 -> 148906644 | I29: =H29 -> 148906644 | J29: =I29 -> 148906644
B30: 용역원가 | G30: =SUM(H30:J30) -> 4913919591 | H30: ='용역원가(24년)'!H32 -> 1637973197 | I30: =H30 -> 1637973197 | J30: =I30 -> 1637973197
B31: 부가가치세(10%) | G31: =SUM(H31:J31) -> 491391936 | H31: ='용역원가(24년)'!H33 -> 163797312 | I31: =H31 -> 163797312 | J31: =I31 -> 163797312
B32: 고정비 운영원가 | G32: =SUM(H32:J32) -> 5405311527 | H32: ='용역원가(24년)'!H34 -> 1801770509 | I32: =H32 -> 1801770509 | J32: =I32 -> 1801770509
A33: 변 동 비 | B33: 변동비부문 | C33: 소모자재비 | G33: =SUM(H33:J33) -> 81000000 | H33: ='용역원가(24년)'!H35 -> 27000000 | I33: =H33 -> 27000000 | J33: =I33 -> 27000000
C34: 수선유지비 | G34: =SUM(H34:J34) -> 1816520000 | H34: ='용역원가(24년)'!H36 -> 635840000 | I34: ='변동)수선유지비'!T30 -> 584840000 | J34: ='변동)수선유지비'!AE30 -> 595840000 | M34: 전문위탁사 자료참조
C35: 측정검사수수료 | G35: =SUM(H35:J35) -> 5409498 | H35: ='용역원가(24년)'!H37 -> 1803166 | I35: =H35 -> 1803166 | J35: =I35 -> 1803166
C36: 안전점검대행비 | G36: =SUM(H36:J36) -> 87840000 | H36: ='용역원가(24년)'!H38 -> 29280000 | I36: =H36 -> 29280000 | J36: =I36 -> 29280000
C37: 차량유지비 | G37: =SUM(H37:J37) -> 177804000 | H37: ='용역원가(24년)'!H39 -> 59268000 | I37: =H37 -> 59268000 | J37: =I37 -> 59268000
C38: 보안관리비 | G38: =SUM(H38:J38) -> 18720000 | H38: ='용역원가(24년)'!H40 -> 6240000 | I38: =H38 -> 6240000 | J38: =I38 -> 6240000
C39: 수집운반비 | G39: =SUM(H39:J39) -> 2.091136e+08 | H39: ='용역원가(24년)'!H41 -> 69704532 | I39: =H39 -> 69704532 | J39: =I39 -> 69704532
C40: 계 | G40: =SUM(H40:J40) -> 2.3964071e+09 | H40: ='용역원가(24년)'!H42 -> 829135680 | I40: =SUM(I33:I39) -> 7.781357e+08 | J40: =SUM(J33:J39) -> 7.891357e+08
...

Sheet 갑지
A1: 운 영 관 리 용 역 예 정 원 가 예 산 서
J3: 설계 | N3: 검산 | R3: 심사 | V3: 팀장 | Z3: 과장
A4: 2023년 7 월 일 설계
A7: =AE12 -> 파주시 운정 자동집하시설 운영비용 원가산정용역
F9: 사업개요 : | I9: =AE12&" : 1식" -> 파주시 운정 자동집하시설 운영비용 원가산정용역 : 1식 | AE9: 위치
AE10: 파주시 운정신도시 집하장(가람집하장, 산내집하장, 한울집하장, 한빛집하장)
E11: ◆ | F11: 전체분(3년간) | K11: : | L11: =차수별용역비!D13 -> 13486280000 | Q11: ="(금"&(NUMBERSTRING(L11,1))&"원)" -> (금일백삼십사억팔천육백이십팔만원) | AE11: 제목
AE12: 파주시 운정 자동집하시설 운영비용 원가산정용역
E14: ◆ | F14: 1차분(2024년) | K14: : | L14: =차수별용역비!D9 -> 4446495000 | Q14: ="(금"&(NUMBERSTRING(L14,1))&"원)" -> (금사십사억사천육백사십구만오천원)
E17: ◆ | F17: 2차분(2025년) | K17: : | L17: =차수별용역비!D10 -> 4471344000 | Q17: ="(금"&(NUMBERSTRING(L17,1))&"원)" -> (금사십사억칠천일백삼십사만사천원)
E20: ◆ | F20: 3차분(2026년) | K20: : | L20: =차수별용역비!D11 -> 4568441000 | Q20: ="(금"&(NUMBERSTRING(L20,1))&"원)" -> (금사십오억육천팔백사십사만일천원)

Sheet 2023년계약원가 비교
A2: 전기대비 용역원가비교표
J4: 단위 : 원/년
E5: 구 분 | G5: 원가계산기준 | H5: 2024년 계약금액 낙찰율적용 | I5: 차액 (원가-계약) | J5: 비 고
A6: 비 목
A7: 고 정 비 | B7: 인 건 비 | C7: 기 본 급 | G7: ='용역원가(24년)'!H7 -> 683461908
C8: 제수당 | E8: 년차수당 | G8: ='용역원가(24년)'!H8 -> 52370400
E9: 연장근로수당 | G9: ='용역원가(24년)'!H9 -> 0
E10: 휴일근로수당 | G10: ='용역원가(24년)'!H10 -> 106873200
E11: 소계 | G11: ='용역원가(24년)'!H11 -> 159243600
C12: 상여금 | G12: ='용역원가(24년)'!H12 -> 227820564 | J12: ="기본급의 "&단위당인건비!I5*100&"% 적용" -> 기본급의 400% 적용
C13: 퇴직급여충당금 | G13: ='용역원가(24년)'!H13 -> 89210352 | J13: (기본급+제수당+상여금)÷12
C14: 계 | G14: ='용역원가(24년)'!H14 -> 1159736424
B15: 고 정 경 비 | C15: 보 험 료 | E15: 산재보험료 | G15: ='용역원가(24년)'!H15 -> 9634584 | J15: ="(기본급+제수당+상여금)×"&K15&"%" -> (기본급+제수당+상여금)×0.9% | K15: ='고정)인적보험료'!M8 -> 0.9
E16: 국민연금 | G16: ='용역원가(24년)'!H16 -> 48173472 | J16: ="(기본급+제수당+상여금)×"&K16&"%" -> (기본급+제수당+상여금)×4.5% | K16: ='고정)인적보험료'!M9 -> 4.5
E17: 고용보험료 | G17: ='용역원가(24년)'!H17 -> 12310836 | J17: ="(기본급+제수당+상여금)×"&K17&"%" -> (기본급+제수당+상여금)×1.15% | K17: ='고정)인적보험료'!M10 -> 1.15
E18: 국민건강보험료 | G18: ='용역원가(24년)'!H18 -> 37950012 | J18: ="(기본급+제수당+상여금)×"&K18&"%" -> (기본급+제수당+상여금)×3.545% | K18: ='고정)인적보험료'!M11 -> 3.545
E19: 노인장기요양보험료 | G19: ='용역원가(24년)'!H19 -> 4861308 | J19: ="건강보험료×"&K19&"%" -> 건강보험료×12.81% | K19: ='고정)인적보험료'!M12 -> 12.81
E20: 임금채권보장보험료 | G20: ='용역원가(24년)'!H20 -> 642132 | J20: ="(기본급+제수당+상여금)×"&K20&"%" -> (기본급+제수당+상여금)×0.06% | K20: ='고정)인적보험료'!M13 -> 0.06
E21: 석면피해구제분담금 | G21: ='용역원가(24년)'!H21 -> 42648 | J21: ="(기본급+제수당+상여금)×"&K21&"%" -> (기본급+제수당+상여금)×0.004% | K21: ='고정)인적보험료'!M14 -> 0.004
C22: 인건비+보험료 | G22: =SUM(G14:G21) -> 1273351416 | H22: 580043006 | I22: =G22-H22 -> 693308410 | J22: 계약금액기준(보험료 포함) | K22: 낙찰율적용
C23: 복리후생비 | G23: ='용역원가(24년)'!H22 -> 58430904 | H23: 15117900 | I23: =G23-H23 -> 43313004
C24: 안전관리비 | G24: ='용역원가(24년)'!H23 -> 21571097 | H24: 1728665 | I24: =G24-H24 -> 19842432
C25: 교육훈련비 | G25: ='용역원가(24년)'!H24 -> 2008764 | H25: 1633976 | I25: =G25-H25 -> 374788
C26: 소모품비 | G26: ='용역원가(24년)'!H25 -> 7529208 | H26: 4429555 | I26: =G26-H26 -> 3099653
C27: 출장여비 | G27: ='용역원가(24년)'!H26 -> 1147932 | H27: 739200 | I27: =G27-H27 -> 408732
C28: 통신 및 우편비 | G28: ='용역원가(24년)'!H27 -> 2076792 | H28: 2194290 | I28: =G28-H28 -> -117498
C29: 수집운반비 | G29: ='용역원가(24년)'!#REF! -> #REF! | I29: =G29-H29 -> #REF! | J29: 신규
C30: 고정경비(보험료제외) | G30: ='용역원가(24년)'!H28-SUM(G15:G21) -> 92764697 | H30: =SUM(H23:H29) -> 25843586 | I30: =G30-H30 -> 66921111
C31: 계 | G31: ='용역원가(24년)'!H28 -> 206379689 | H31: =H30 -> 25843586 | I31: =G31-H31 -> 180536103 | J31: 계약금액기준(보험료 미포함)
B32: 순용역원가 | G32: ='용역원가(24년)'!H29 -> 1366116113 | H32: =SUM(H22,H30) -> 605886592 | I32: =G32-H32 -> 760229521 | J32: 인건비+경비
B33: ="일반관리비("&K33&"%)" -> 일반관리비(9%) | G33: ='용역원가(24년)'!H30 -> 122950440 | H33: 19989714 | I33: =G33-H33 -> 102960726 | J33: ="순용역원가×"&K33&"%(5%->10%)" -> 순용역원가×9%(5%->10%) | K33: ='용역원가(24년)'!K30 -> 9
B34: ="이윤("&K34&"%)" -> 이윤(10%) | G34: ='용역원가(24년)'!H31 -> 148906644 | H34: 38438727 | I34: =G34-H34 -> 110467917 | J34: ="(순용역원가+일반관리비)×"&K34&"%" -> (순용역원가+일반관리비)×10% | K34: ='용역원가(24년)'!K31 -> 10
B35: 용역원가 | G35: ='용역원가(24년)'!H32 -> 1637973197 | H35: =SUM(H32:H34) -> 664315033 | I35: =G35-H35 -> 973658164 | J35: 순용역원가+일.관+이윤
B36: 부가가치세(10%) | G36: ='용역원가(24년)'!H33 -> 163797312 | H36: 66431503 | I36: =G36-H36 -> 97365809 | J36: 용역원가×10%
B37: 고정비 운영원가 | G37: ='용역원가(24년)'!H34 -> 1801770509 | H37: =SUM(H35:H36) -> 730746536 | I37: =G37-H37 -> 1071023973 | J37: 용역원가+부가가치세
A38: 변 동 비 | B38: 변동비부문 | C38: 소모자재비 | G38: ='용역원가(24년)'!H35 -> 27000000 | H38: 21000000 | I38: =G38-H38 -> 6000000
C39: 수선유지비 | G39: ='용역원가(24년)'!H36 -> 635840000 | H39: 198629639 | I39: =G39-H39 -> 437210361
C40: 측정검사수수료 | G40: ='용역원가(24년)'!H37 -> 1803166 | H40: 5894727 | I40: =G40-H40 -> -4091561
C41: 안전점검대행비 | G41: ='용역원가(24년)'!H38 -> 29280000 | H41: 27480000 | I41: =G41-H41 -> 1800000
C42: 차량유지비 | G42: ='용역원가(24년)'!H39 -> 59268000 | H42: 46523360 | I42: =G42-H42 -> 12744640
...

Sheet 간지#
D3: 1. 운영원가 산정
F7: [ 표 : 1 ] | H7: =용역원가집계!$A$2 -> 용역원가집계표 | Z7: =용역원가집계!$A$1 -> [ 표 : 1 ]
F8: [ 표 : 2 ] | H8: ='용역원가(24년)'!$A$2 -> 용역원가계산서(2024년) | Z8: ='용역원가(24년)'!$A$1 -> [ 표 : 2 ]
F9: [ 표 : 3 ] | H9: ='용역원가(25년) '!$A$2 -> 용역원가계산서(2025년)
F10: [ 표 : 4 ] | H10: ='용역원가(26년)'!$A$2 -> 용역원가계산서(2026년)
F11: [ 표 : 5 ] | H11: =인건비집계!$A$2 -> 인건비집계표 | Z11: =인건비집계!$A$1 -> [ 표 : 5 ]
F12: [ 표 : 6 ] | H12: =제수당집계!$A$2 -> 제수당집계표 | Z12: =제수당집계!$A$1 -> [ 표 : 6 ]
F13: [ 표 : 7 ] | H13: =단위당인건비!$A$2 -> 직책별 단위(1인)당 인건비산출표 | Z13: =단위당인건비!$A$1 -> [ 표 : 7 ]
F14: [ 표 : 8 ] | H14: =월기본급!$A$2 -> 월(M/M)당기본급산출표 | Z14: =월기본급!$A$1 -> [ 표 : 8 ]
F15: [ 표 : 9 ] | H15: =기본급추정!$A$2 -> 엔지니어링기술자노임단가 기본급추정 산출표 | Z15: =기본급추정!$A$1 -> [ 표 : 9 ]
F16: [ 표 : 10 ] | H16: =인건비산정기준!$A$2 -> 인건비산정기준 및 관련법규 | Z16: =엔지니어노임!$A$1 -> [ 표 : 10 ]
F17: [ 표 : 11 ] | H17: =보험료산정기준!$A$2 -> 보험료산정기준표 | Z17: =엔지니어노임!$A$1 -> [ 표 : 10 ]
F18: [ 표 : 12 ] | H18: =투입인원!$A$2 -> 적용직종 및 근무형태 | Z18: =인건비산정기준!$A$1 -> [ 표 : 10 ]
F19: [ 표 : 13 ] | H19: =근무일수!$A$2 -> 용역기간현황표 | Z19: =투입인원!$A$1 -> [ 표 : 12 ]
F20: [ 표 : 14 ] | H20: =가동시간!$A$2 -> 2023년 설비가동시간 및 처리량 산출표 | Z20: =근무일수!$A$1 -> [ 표 : 13 ]
F21: [ 표 : 15 ] | H21: =기간현황!$A$2 -> 2023년 상반기 용역기간현황표 | Z21: =가동시간!$A$1 -> [ 표 : 14 ]
F22: [ 표 : 16 ] | H22: =경비집계!$A$2 -> 경비집계표 | Z22: =기간현황!$A$1 -> [ 표 : 15 ]
F23: [ 표 : 17 ] | H23: ='고정)인적보험료집계'!$A$2 -> 보험료집계표 | Z23: =경비집계!$A$1 -> [ 표 : 16 ]
F24: [ 표 : 18 ] | H24: ='고정)인적보험료'!$A$2 -> 단위(1인)당 보험료산출표 | Z24: ='고정)인적보험료집계'!$A$1 -> [ 표 : 17 ]
F25: [ 표 : 19 ] | H25: ='고정)복리후생비집계'!$A$2 -> 복리후생비집계표 | Z25: ='고정)인적보험료'!$A$1 -> [ 표 : 18 ]
F26: [ 표 : 20 ] | H26: ='고정)피복비'!$A$2 -> 단위(1인)당 피복비산출표 | Z26: ='고정)복리후생비집계'!$A$1 -> [ 표 : 19 ]
F27: [ 표 : 21 ] | H27: ='고정)식대'!$A$2 -> 단위(1인)당 식대산출표 | Z27: ='고정)피복비'!$A$1 -> [ 표 : 20 ]
F28: [ 표 : 22 ] | H28: ='고정)건강검진비'!$A$2 -> 단위(1인)당 건강검진비산출표 | Z28: ='고정)식대'!$A$1 -> [ 표 : 21 ]
F29: [ 표 : 23 ] | H29: ='고정)의약품'!$A$2 -> 단위(1인)당 의약품비산출표 | Z29: ='고정)건강검진비'!$A$1 -> [ 표 : 22 ]
F30: [ 표 : 24 ] | H30: ='고정)안전관리비'!$A$2 -> 안전관리비산출표 | Z30: ='고정)의약품'!$A$1 -> [ 표 : 23 ]
F31: [ 표 : 25 ] | H31: ='고정)교육훈련비'!$A$2 -> 교육훈련비산출표 | Z31: ='고정)안전관리비'!$A$1 -> [ 표 : 24 ]
F32: [ 표 : 26 ] | H32: ='고정)소모품비'!$A$2 -> 소모품비산출표 | Z32: ='고정)교육훈련비'!$A$1 -> [ 표 : 25 ]
F33: [ 표 : 27 ] | H33: ='고정)출장여비'!$A$2 -> 출장여비산출표 | Z33: ='고정)소모품비'!$A$1 -> [ 표 : 26 ]
F34: [ 표 : 28 ] | H34: =운임!$A$2 -> 국내여비운임조사표 | Z34: ='고정)출장여비'!$A$1 -> [ 표 : 27 ]
F35: [ 표 : 29 ] | H35: ='고정)통신비'!$A$2 -> 통신비산출표 | Z35: =운임!$A$1 -> [ 표 : 28 ]
F36: [ 표 : 30 ] | H36: ='변동)소모자재비'!$A$2 -> 소모자재비산출표 | Z36: ='고정)통신비'!$A$1 -> [ 표 : 29 ]
F37: [ 표 : 31 ] | H37: ='변동)수선유지비'!$A$2 -> 수선유지비산출표 | Z37: ='변동)소모자재비'!$A$1 -> [ 표 : 30 ]
F38: [ 표 : 32 ] | H38: ='변동)측정검사수수료'!$A$2 -> 측정검사수수료산출표 | Z38: ='변동)수선유지비'!$A$1 -> [ 표 : 31 ]
F39: [ 표 : 33 ] | H39: ='변동)안전점검대행비'!$A$2 -> 안전점검 대행수수료산출표 | Z39: ='변동)측정검사수수료'!$A$1 -> [ 표 : 32 ]
F40: [ 표 : 34 ] | H40: ='변동)차량유지비'!$A$2 -> 차량유지비산출표 | Z40: ='변동)안전점검대행비'!$A$1 -> [ 표 : 33 ]
F41: [ 표 : 35 ] | H41: ='변동)보안관리비'!$A$2 -> 보안관리비산출표 | Z41: ='변동)차량유지비'!$A$1 -> [ 표 : 34 ]
F42: [ 표 : 36 ] | H42: ='변동)수집운반비'!$A$2 -> 수집운반비 산출표 | Z42: ='변동)보안관리비'!$A$1 -> [ 표 : 35 ]
F43: [ 표 : 37 ] | H43: ='변동-대)전력비'!$A$2 -> 전력비산출표 | Z43: ='변동-대)전력비'!$A$1 -> [ 표 : 37 ]
F44: [ 표 : 38 ] | H44: =전력사용량!$A$2 -> 전력사용량(kWh)산출표 | Z44: =전력사용량!$A$1 -> [ 표 : 38 ]
F45: [ 표 : 39 ] | H45: ='변동-대)수도광열비'!$A$2 -> 수도광열비산출표 | Z45: ='변동-대)수도광열비'!$A$1 -> [ 표 : 39 ]
...

Sheet 차수별용역비
A1: ="[ 표 : "&F1&" ] " -> [ 표 : 1 ] | F1: 1
A2: 용역원가집계표
H3: 비율
E4: 단위 : 원 | G4: 일반관리비 | H4: 10
A5: 구 분 | B5: 용역기간 | C5: 위탁기간 (월) | D5: 차수별용역비 | E5: 비 고 | G5: 이윤 | H5: 10
A9: 1차년도 | B9: 2024. 1. 01. ∼ 2024. 12. 31. | C9: 12 | D9: ='36개월총괄'!H49 -> 4446495000
A10: 2차년도 | B10: 2025. 1. 01. ∼ 2025. 12. 31. | C10: 12 | D10: ='36개월총괄'!I49 -> 4471344000
A11: 3차년도 | B11: 2026. 1. 01. ∼ 2026. 12. 31. | C11: 12 | D11: ='36개월총괄'!J49 -> 4568441000
A13: 총 용역비 | C13: =SUM(C8:C12) -> 36 | D13: =SUM(D8:D12) -> 13486280000 | E13: 3년
A14: ="주 1) 위탁기간(월) : 제시된 용역기간 적용" -> 주 1) 위탁기간(월) : 제시된 용역기간 적용
A15: =" 2) 차수별용역비 : 월간용역비 ×위탁기간(월)" -> 2) 차수별용역비 : 월간용역비 ×위탁기간(월)
A16: 3) 상기금액은 처리장 수집운반비 및 부가가치세 포함 금액임

Sheet 용역원가집계
A1: ="[ 표 : "&F1&" ] " -> [ 표 : 1 ] | F1: 1
A2: 용역원가집계표
H3: 비율
E4: 단위 : 원 | G4: 일반관리비 | H4: 10 | I4: =일반관리비!E8 -> 9
A5: 구 분 | B5: 월간용역비 | C5: 위탁기간 (월) | D5: 연간용역비 | E5: 비 고 | G5: 이윤 | H5: 10
B7: 주 1) | C7: 주 2) | D7: 주 3)
A8: 1차 용역비 | B8: ='용역원가(24년)'!G51 -> 370541000 | C8: 12 | D8: ='용역원가(24년)'!H51 -> 4446495000
A9: 2차 용역비 | B9: ='용역원가(25년) '!G52 -> 372612000 | C9: 12 | D9: =차수별용역비!D10 -> 4471344000
A10: 3차 용역비 | B10: ='용역원가(26년)'!G51 -> 380703000 | C10: 12 | D10: =차수별용역비!D11 -> 4568441000
A12: 총 용역비 | D12: =SUM(D8:D10) -> 13486280000 | E12: 3년
A13: ="주 1) 월간용역비 : "&'용역원가(24년)'!A1&'용역원가(24년)'!A2&" 참조" -> 주 1) 월간용역비 : [ 표 : 2 ] 용역원가계산서(2024년) 참조
A14: =" 2) 위탁기간(월) : 제시된 용역기간 적용" -> 2) 위탁기간(월) : 제시된 용역기간 적용
A15: =" 3) 연간용역비 : 월간용역비 ×위탁기간(년)" -> 3) 연간용역비 : 월간용역비 ×위탁기간(년)
A16: 4) 상기금액은 처리장 수집운반비 및 부가가치세 포함 금액임

Sheet 용역원가(24년)
A1: ="[ 표 : "&K1&" ] " -> [ 표 : 2 ] | K1: =용역원가집계!F1+1 -> 2
A2: 용역원가계산서(2024년)
J4: 단위 : 원/월
E5: 구 분 | G5: 월간용역비 | H5: 연간용역비 | J5: 비 고
A6: 비 목
A7: 고 정 비 | B7: 인 건 비 | C7: 기 본 급 | G7: =인건비집계!H25 -> 56955159 | H7: =TRUNC(G7*12) -> 683461908 | I7: 692320572 | L7: =인건비집계!H25 -> 56955159 | M7: =G7-L7 -> 0
C8: 제수당 | E8: 년차수당 | G8: =제수당집계!H25 -> 4364200 | H8: =TRUNC(G8*12) -> 52370400 | I8: 53049240
E9: 연장근로수당 | G9: =제수당집계!K25 -> 0 | H9: =TRUNC(G9*12) -> 0 | I9: 0
E10: 휴일근로수당 | G10: =제수당집계!N25 -> 8906100 | H10: =TRUNC(G10*12) -> 106873200 | I10: 108339492
E11: 소계 | G11: =SUM(G8:G10) -> 13270300 | H11: =TRUNC(G11*12) -> 159243600 | I11: =SUM(I8:I10) -> 161388732 | L11: =인건비집계!K25 -> 13270300 | M11: =G11-L11 -> 0
C12: 상여금 | G12: =인건비집계!N25 -> 18985047 | H12: =TRUNC(G12*12) -> 227820564 | I12: 230773464 | J12: ="기본급의 "&단위당인건비!I5*100&"% 적용" -> 기본급의 400% 적용 | L12: =인건비집계!N25 -> 18985047 | M12: =G12-L12 -> 0
C13: 퇴직급여충당금 | G13: =인건비집계!Q25 -> 7434196 | H13: =TRUNC(G13*12) -> 89210352 | I13: 90373416 | J13: (기본급+제수당+상여금)÷12 | L13: =인건비집계!Q25 -> 7434196 | M13: =G13-L13 -> 0
C14: 계 | G14: =SUM(G7,G11,G12,G13) -> 96644702 | H14: =TRUNC(G14*12) -> 1159736424 | I14: =I7+I11+I12+I13 -> 1174856184 | J14: =인건비집계!$A$1&"참조" -> [ 표 : 5 ] 참조
B15: 고 정 경 비 | C15: 보 험 료 | E15: 산재보험료 | G15: =경비집계!F7 -> 802882 | H15: =TRUNC(G15*12) -> 9634584 | I15: 7828632 | J15: ="(기본급+제수당+상여금)×"&K15&"%" -> (기본급+제수당+상여금)×0.9% | K15: ='고정)인적보험료'!M8 -> 0.9 | L15: =경비집계!F7 -> 802882 | M15: =L15-G15 -> 0 | O15: 사후정산
E16: 국민연금 | G16: =경비집계!F8 -> 4014456 | H16: =TRUNC(G16*12) -> 48173472 | I16: 39143556 | J16: ="(기본급+제수당+상여금)×"&K16&"%" -> (기본급+제수당+상여금)×4.5% | K16: ='고정)인적보험료'!M9 -> 4.5 | L16: =경비집계!F8 -> 4014456 | M16: =L16-G16 -> 0 | O16: =H16*3 -> 144520416
E17: 고용보험료 | G17: =경비집계!F9 -> 1025903 | H17: =TRUNC(G17*12) -> 12310836 | I17: 10003260 | J17: ="(기본급+제수당+상여금)×"&K17&"%" -> (기본급+제수당+상여금)×1.15% | K17: ='고정)인적보험료'!M10 -> 1.15 | L17: =경비집계!F9 -> 1025903 | M17: =L17-G17 -> 0
E18: 국민건강보험료 | G18: =경비집계!F10 -> 3162501 | H18: =TRUNC(G18*12) -> 37950012 | I18: 30836436 | J18: ="(기본급+제수당+상여금)×"&K18&"%" -> (기본급+제수당+상여금)×3.545% | K18: ='고정)인적보험료'!M11 -> 3.545 | L18: =경비집계!F10 -> 3162501 | M18: =L18-G18 -> 0 | O18: =H18*3 -> 113850036
E19: 노인장기요양보험료 | G19: =경비집계!F11 -> 405109 | H19: =TRUNC(G19*12) -> 4861308 | I19: 3950064 | J19: ="건강보험료×"&K19&"%" -> 건강보험료×12.81% | K19: ='고정)인적보험료'!M12 -> 12.81 | L19: =경비집계!F11 -> 405109 | M19: =L19-G19 -> 0 | O19: =H19*3 -> 14583924
E20: 임금채권보장보험료 | G20: =경비집계!F12 -> 53511 | H20: =TRUNC(G20*12) -> 642132 | I20: 521808 | J20: ="(기본급+제수당+상여금)×"&K20&"%" -> (기본급+제수당+상여금)×0.06% | K20: ='고정)인적보험료'!M13 -> 0.06 | L20: =경비집계!F12 -> 53511 | M20: =L20-G20 -> 0
E21: 석면피해구제분담금 | G21: =경비집계!F13 -> 3554 | H21: =TRUNC(G21*12) -> 42648 | I21: 34692 | J21: ="(기본급+제수당+상여금)×"&K21&"%" -> (기본급+제수당+상여금)×0.004% | K21: ='고정)인적보험료'!M14 -> 0.004 | L21: =경비집계!F13 -> 3554 | M21: =L21-G21 -> 0
C22: 복리후생비 | G22: =경비집계!F15 -> 4869242 | H22: =TRUNC(G22*12) -> 58430904 | I22: 58430904 | L22: =경비집계!F15 -> 4869242 | M22: =L22-G22 -> 0
C23: 안전관리비 | G23: =경비집계!F16 -> 1797591.5 | H23: =TRUNC(G23*12) -> 21571097 | I23: 13355725 | L23: =경비집계!F16 -> 1797591.5 | M23: =L23-G23 -> 0
C24: 교육훈련비 | G24: =경비집계!F17 -> 167397 | H24: =TRUNC(G24*12) -> 2008764 | I24: 2008764 | L24: =경비집계!F17 -> 167397 | M24: =L24-G24 -> 0
C25: 소모품비 | G25: =경비집계!F18 -> 627434 | H25: =TRUNC(G25*12) -> 7529208 | I25: 7529208 | L25: =경비집계!F18 -> 627434 | M25: =L25-G25 -> 0
C26: 출장여비 | G26: =경비집계!F19 -> 95661 | H26: =TRUNC(G26*12) -> 1147932 | I26: 1147932 | L26: =경비집계!F19 -> 95661 | M26: =L26-G26 -> 0
C27: 통신 및 우편비 | G27: =경비집계!F20 -> 173066 | H27: =TRUNC(G27*12) -> 2076792 | I27: 2076792 | L27: =경비집계!F20 -> 173066 | M27: =L27-G27 -> 0
C28: 계 | G28: =SUM(G15:G27) -> 17198307 | H28: =SUM(H15:H27) -> 206379689 | I28: =SUM(I15:I27) -> 176867773 | J28: =경비집계!$A$1&"참조" -> [ 표 : 16 ] 참조 | L28: =경비집계!F22 -> 17198307 | M28: =L28-G28 -> 0
B29: 순용역원가 | G29: =SUM(G14,G28) -> 1.1384301e+08 | H29: =TRUNC(G29*12) -> 1366116113 | I29: =I14+I28 -> 1351723957 | J29: 인건비+경비
B30: ="일반관리비("&K30&"%)" -> 일반관리비(9%) | G30: =TRUNC(G29*$K$30%,0) -> 10245870 | H30: =TRUNC(G30*12) -> 122950440 | I30: =I29*0.09 -> 1.2165516e+08 | J30: ="순용역원가×"&K30&"%" -> 순용역원가×9% | K30: 9 | L30: =일반관리비!F10 -> 10245870 | M30: =L30-G30 -> 0
B31: ="이윤("&K31&"%)" -> 이윤(10%) | G31: =TRUNC((SUM(G14,G28,G30))*$K$31%,0) -> 12408887 | H31: =TRUNC(G31*12) -> 148906644 | I31: =(I14+I28+I30)*0.1 -> 1.4733791e+08 | J31: ="(순용역원가+일반관리비)×"&K31&"%" -> (순용역원가+일반관리비)×10% | K31: =용역원가집계!H5 -> 10 | L31: =이윤!G10 -> 12408887 | M31: =L31-G31 -> 0
B32: 용역원가 | G32: =SUM(G29:G31) -> 1.3649777e+08 | H32: =TRUNC(G32*12) -> 1637973197 | I32: =SUM(I29:I31) -> 1.620717e+09 | J32: 순용역원가+일.관+이윤
B33: 부가가치세(10%) | G33: =TRUNC((G32)*10%,0) -> 13649776 | H33: =TRUNC(G33*12) -> 163797312 | I33: =I32*0.1 -> 1.620717e+08 | J33: 용역원가×10%
B34: 고정비 운영원가 | G34: =SUM(G32:G33) -> 1.5014754e+08 | H34: =TRUNC(G34*12) -> 1801770509 | I34: 1782788713 | J34: 용역원가+부가가치세 | O34: =H34*3 -> 5405311527
A35: 변 동 비 | B35: 변동비부문 | C35: 소모자재비 | G35: =경비집계!F23 -> 2250000 | H35: ='변동)소모자재비'!H13 -> 27000000 | I35: 27000000 | L35: =경비집계!F23 -> 2250000 | M35: =L35-G35 -> 0
C36: 수선유지비 | G36: =경비집계!F24 -> 52986666 | H36: ='변동)수선유지비'!H30 -> 635840000 | I36: 635840000 | L36: =경비집계!F24 -> 52986666 | M36: =L36-G36 -> 0
C37: 측정검사수수료 | G37: =경비집계!F25 -> 150263 | H37: ='변동)측정검사수수료'!H12 -> 1803166 | I37: 1803166 | L37: =경비집계!F25 -> 150263 | M37: =L37-G37 -> 0
C38: 안전점검대행비 | G38: =경비집계!F26 -> 2440000 | H38: ='변동)안전점검대행비'!H14 -> 29280000 | I38: 29280000 | L38: =경비집계!F26 -> 2440000 | M38: =L38-G38 -> 0
C39: 차량유지비 | G39: =경비집계!F27 -> 4939000 | H39: ='변동)차량유지비'!H15 -> 59268000 | I39: 59268000 | L39: =경비집계!F27 -> 4939000 | M39: =L39-G39 -> 0
C40: 보안관리비 | G40: =경비집계!F28 -> 520000 | H40: ='변동)보안관리비'!H11 -> 6240000 | I40: 6240000 | L40: =경비집계!F28 -> 520000 | M40: =L40-G40 -> 0
C41: 수집운반비 | G41: =경비집계!F29 -> 5808711 | H41: ='변동)수집운반비'!E12 -> 69704532 | I41: 69704532 | J41: 부가세법 제26조, 동법 시행령 제35조 참조 | L41: =경비집계!F29 -> 5808711 | M41: =L41-G41 -> 0
...

Sheet 용역원가(25년) 
A1: ="[ 표 : "&J1&" ] " -> [ 표 : 3 ] | J1: ='용역원가(24년)'!K1+1 -> 3
A2: 용역원가계산서(2025년)
I4: 단위 : 원/월
E5: 구 분 | G5: 월간용역비 | H5: 연간용역비 | I5: 비 고
A6: 비 목
A7: 고 정 비 | B7: 인 건 비 | C7: 기 본 급 | G7: =인건비집계!H25 -> 56955159 | H7: =TRUNC(G7*12) -> 683461908 | K7: =인건비집계!H25 -> 56955159 | L7: =G7-K7 -> 0
C8: 제수당 | E8: 년차수당 | G8: =제수당집계!H25 -> 4364200 | H8: =TRUNC(G8*12) -> 52370400
E9: 연장근로수당 | G9: =제수당집계!K25 -> 0 | H9: =TRUNC(G9*12) -> 0
E10: 휴일근로수당 | G10: =제수당집계!N25 -> 8906100 | H10: =TRUNC(G10*12) -> 106873200
E11: 소계 | G11: =SUM(G8:G10) -> 13270300 | H11: =TRUNC(G11*12) -> 159243600 | K11: =인건비집계!K25 -> 13270300 | L11: =G11-K11 -> 0
C12: 상여금 | G12: =인건비집계!N25 -> 18985047 | H12: =TRUNC(G12*12) -> 227820564 | I12: ="기본급의 "&단위당인건비!I5*100&"% 적용" -> 기본급의 400% 적용 | K12: =인건비집계!N25 -> 18985047 | L12: =G12-K12 -> 0
C13: 퇴직급여충당금 | G13: =인건비집계!Q25 -> 7434196 | H13: =TRUNC(G13*12) -> 89210352 | I13: (기본급+제수당+상여금)÷12 | K13: =인건비집계!Q25 -> 7434196 | L13: =G13-K13 -> 0
C14: 계 | G14: =SUM(G7,G11,G12,G13) -> 96644702 | H14: =TRUNC(G14*12) -> 1159736424 | I14: =인건비집계!$A$1&"참조" -> [ 표 : 5 ] 참조
B15: 고 정 경 비 | C15: 보 험 료 | E15: 산재보험료 | G15: =경비집계!F7 -> 802882 | H15: =TRUNC(G15*12) -> 9634584 | I15: ="(기본급+제수당+상여금)×"&J15&"%" -> (기본급+제수당+상여금)×0.9% | J15: ='고정)인적보험료'!M8 -> 0.9 | K15: =경비집계!F7 -> 802882 | L15: =K15-G15 -> 0 | N15: 사후정산
E16: 국민연금 | G16: =경비집계!F8 -> 4014456 | H16: =TRUNC(G16*12) -> 48173472 | I16: ="(기본급+제수당+상여금)×"&J16&"%" -> (기본급+제수당+상여금)×4.5% | J16: ='고정)인적보험료'!M9 -> 4.5 | K16: =경비집계!F8 -> 4014456 | L16: =K16-G16 -> 0 | N16: =H16*3 -> 144520416
E17: 고용보험료 | G17: =경비집계!F9 -> 1025903 | H17: =TRUNC(G17*12) -> 12310836 | I17: ="(기본급+제수당+상여금)×"&J17&"%" -> (기본급+제수당+상여금)×1.15% | J17: ='고정)인적보험료'!M10 -> 1.15 | K17: =경비집계!F9 -> 1025903 | L17: =K17-G17 -> 0
E18: 국민건강보험료 | G18: =경비집계!F10 -> 3162501 | H18: =TRUNC(G18*12) -> 37950012 | I18: ="(기본급+제수당+상여금)×"&J18&"%" -> (기본급+제수당+상여금)×3.545% | J18: ='고정)인적보험료'!M11 -> 3.545 | K18: =경비집계!F10 -> 3162501 | L18: =K18-G18 -> 0 | N18: =H18*3 -> 113850036
E19: 노인장기요양보험료 | G19: =경비집계!F11 -> 405109 | H19: =TRUNC(G19*12) -> 4861308 | I19: ="건강보험료×"&J19&"%" -> 건강보험료×12.81% | J19: ='고정)인적보험료'!M12 -> 12.81 | K19: =경비집계!F11 -> 405109 | L19: =K19-G19 -> 0 | N19: =H19*3 -> 14583924
E20: 임금채권보장보험료 | G20: =경비집계!F12 -> 53511 | H20: =TRUNC(G20*12) -> 642132 | I20: ="(기본급+제수당+상여금)×"&J20&"%" -> (기본급+제수당+상여금)×0.06% | J20: ='고정)인적보험료'!M13 -> 0.06 | K20: =경비집계!F12 -> 53511 | L20: =K20-G20 -> 0
E21: 석면피해구제분담금 | G21: =경비집계!F13 -> 3554 | H21: =TRUNC(G21*12) -> 42648 | I21: ="(기본급+제수당+상여금)×"&J21&"%" -> (기본급+제수당+상여금)×0.004% | J21: ='고정)인적보험료'!M14 -> 0.004 | K21: =경비집계!F13 -> 3554 | L21: =K21-G21 -> 0
C22: 복리후생비 | G22: =경비집계!F15 -> 4869242 | H22: =TRUNC(G22*12) -> 58430904 | K22: =경비집계!F15 -> 4869242 | L22: =K22-G22 -> 0
C23: 안전관리비 | G23: =경비집계!F16 -> 1797591.5 | H23: =TRUNC(G23*12) -> 21571097 | K23: =경비집계!F16 -> 1797591.5 | L23: =K23-G23 -> 0
C24: 교육훈련비 | G24: =경비집계!F17 -> 167397 | H24: =TRUNC(G24*12) -> 2008764 | K24: =경비집계!F17 -> 167397 | L24: =K24-G24 -> 0
C25: 소모품비 | G25: =경비집계!F18 -> 627434 | H25: =TRUNC(G25*12) -> 7529208 | K25: =경비집계!F18 -> 627434 | L25: =K25-G25 -> 0
C26: 출장여비 | G26: =경비집계!F19 -> 95661 | H26: =TRUNC(G26*12) -> 1147932 | K26: =경비집계!F19 -> 95661 | L26: =K26-G26 -> 0
C27: 통신 및 우편비 | G27: =경비집계!F20 -> 173066 | H27: =TRUNC(G27*12) -> 2076792 | K27: =경비집계!F20 -> 173066 | L27: =K27-G27 -> 0
C29: 계 | G29: =SUM(G15:G28) -> 17198307 | H29: =SUM(H15:H28) -> 206379689 | I29: =경비집계!$A$1&"참조" -> [ 표 : 16 ] 참조 | K29: =경비집계!F22 -> 17198307 | L29: =K29-G29 -> 0
B30: 순용역원가 | G30: =SUM(G14,G29) -> 1.1384301e+08 | H30: =TRUNC(G30*12) -> 1366116113 | I30: 인건비+경비
B31: ="일반관리비("&J31&"%)" -> 일반관리비(9%) | G31: =TRUNC(G30*$J$31%,0) -> 10245870 | H31: =TRUNC(G31*12) -> 122950440 | I31: ="순용역원가×"&J31&"%" -> 순용역원가×9% | J31: 9 | K31: =일반관리비!F10 -> 10245870 | L31: =K31-G31 -> 0
B32: ="이윤("&J32&"%)" -> 이윤(10%) | G32: =TRUNC((SUM(G14,G29,G31))*$J$32%,0) -> 12408887 | H32: =TRUNC(G32*12) -> 148906644 | I32: ="(순용역원가+일반관리비)×"&J32&"%" -> (순용역원가+일반관리비)×10% | J32: =용역원가집계!H5 -> 10 | K32: =이윤!G10 -> 12408887 | L32: =K32-G32 -> 0
B33: 용역원가 | G33: =SUM(G30:G32) -> 1.3649777e+08 | H33: =TRUNC(G33*12) -> 1637973197 | I33: 순용역원가+일.관+이윤
B34: 부가가치세(10%) | G34: =TRUNC((G33)*10%,0) -> 13649776 | H34: =TRUNC(G34*12) -> 163797312 | I34: 용역원가×10%
B35: 고정비 운영원가 | G35: =SUM(G33:G34) -> 1.5014754e+08 | H35: =TRUNC(G35*12) -> 1801770509 | I35: 용역원가+부가가치세 | N35: =H35*3 -> 5405311527
A36: 변 동 비 | B36: 변동비부문 | C36: 소모자재비 | G36: =경비집계!F23 -> 2250000 | H36: ='변동)소모자재비'!H13 -> 27000000 | K36: =경비집계!F23 -> 2250000 | L36: =K36-G36 -> 0
C37: 수선유지비 | G37: ='변동)수선유지비'!T31 -> 48736666 | H37: ='변동)수선유지비'!T30 -> 584840000 | K37: =경비집계!F24 -> 52986666 | L37: =K37-G37 -> 4250000
C38: 측정검사수수료 | G38: =경비집계!F25 -> 150263 | H38: ='변동)측정검사수수료'!H12 -> 1803166 | K38: =경비집계!F25 -> 150263 | L38: =K38-G38 -> 0
C39: 안전점검대행비 | G39: =경비집계!F26 -> 2440000 | H39: ='변동)안전점검대행비'!H14 -> 29280000 | K39: =경비집계!F26 -> 2440000 | L39: =K39-G39 -> 0
C40: 차량유지비 | G40: =경비집계!F27 -> 4939000 | H40: ='변동)차량유지비'!H15 -> 59268000 | K40: =경비집계!F27 -> 4939000 | L40: =K40-G40 -> 0
C41: 보안관리비 | G41: =경비집계!F28 -> 520000 | H41: ='변동)보안관리비'!H11 -> 6240000 | K41: =경비집계!F28 -> 520000 | L41: =K41-G41 -> 0
C42: 수집운반비 | G42: =경비집계!F29 -> 5808711 | H42: ='변동)수집운반비'!E12 -> 69704532 | I42: 부가세법 제26조, 동법 시행령 제35조 참조 | K42: =경비집계!F29 -> 5808711 | L42: =K42-G42 -> 0
...

Sheet 용역원가(26년)
A1: ="[ 표 : "&J1&" ] " -> [ 표 : 4 ] | J1: ='용역원가(25년) '!J1+1 -> 4
A2: 용역원가계산서(2026년)
I4: 단위 : 원/월
E5: 구 분 | G5: 월간용역비 | H5: 연간용역비 | I5: 비 고
A6: 비 목
A7: 고 정 비 | B7: 인 건 비 | C7: 기 본 급 | G7: =인건비집계!H25 -> 56955159 | H7: =TRUNC(G7*12) -> 683461908 | K7: =인건비집계!H25 -> 56955159 | L7: =G7-K7 -> 0
C8: 제수당 | E8: 년차수당 | G8: =제수당집계!H25 -> 4364200 | H8: =TRUNC(G8*12) -> 52370400
E9: 연장근로수당 | G9: =제수당집계!K25 -> 0 | H9: =TRUNC(G9*12) -> 0
E10: 휴일근로수당 | G10: =제수당집계!N25 -> 8906100 | H10: =TRUNC(G10*12) -> 106873200
E11: 소계 | G11: =SUM(G8:G10) -> 13270300 | H11: =TRUNC(G11*12) -> 159243600 | K11: =인건비집계!K25 -> 13270300 | L11: =G11-K11 -> 0
C12: 상여금 | G12: =인건비집계!N25 -> 18985047 | H12: =TRUNC(G12*12) -> 227820564 | I12: ="기본급의 "&단위당인건비!I5*100&"% 적용" -> 기본급의 400% 적용 | K12: =인건비집계!N25 -> 18985047 | L12: =G12-K12 -> 0
C13: 퇴직급여충당금 | G13: =인건비집계!Q25 -> 7434196 | H13: =TRUNC(G13*12) -> 89210352 | I13: (기본급+제수당+상여금)÷12 | K13: =인건비집계!Q25 -> 7434196 | L13: =G13-K13 -> 0
C14: 계 | G14: =SUM(G7,G11,G12,G13) -> 96644702 | H14: =TRUNC(G14*12) -> 1159736424 | I14: =인건비집계!$A$1&"참조" -> [ 표 : 5 ] 참조
B15: 고 정 경 비 | C15: 보 험 료 | E15: 산재보험료 | G15: =경비집계!F7 -> 802882 | H15: =TRUNC(G15*12) -> 9634584 | I15: ="(기본급+제수당+상여금)×"&J15&"%" -> (기본급+제수당+상여금)×0.9% | J15: ='고정)인적보험료'!M8 -> 0.9 | K15: =경비집계!F7 -> 802882 | L15: =K15-G15 -> 0 | N15: 사후정산
E16: 국민연금 | G16: =경비집계!F8 -> 4014456 | H16: =TRUNC(G16*12) -> 48173472 | I16: ="(기본급+제수당+상여금)×"&J16&"%" -> (기본급+제수당+상여금)×4.5% | J16: ='고정)인적보험료'!M9 -> 4.5 | K16: =경비집계!F8 -> 4014456 | L16: =K16-G16 -> 0 | N16: =H16*3 -> 144520416
E17: 고용보험료 | G17: =경비집계!F9 -> 1025903 | H17: =TRUNC(G17*12) -> 12310836 | I17: ="(기본급+제수당+상여금)×"&J17&"%" -> (기본급+제수당+상여금)×1.15% | J17: ='고정)인적보험료'!M10 -> 1.15 | K17: =경비집계!F9 -> 1025903 | L17: =K17-G17 -> 0
E18: 국민건강보험료 | G18: =경비집계!F10 -> 3162501 | H18: =TRUNC(G18*12) -> 37950012 | I18: ="(기본급+제수당+상여금)×"&J18&"%" -> (기본급+제수당+상여금)×3.545% | J18: ='고정)인적보험료'!M11 -> 3.545 | K18: =경비집계!F10 -> 3162501 | L18: =K18-G18 -> 0 | N18: =H18*3 -> 113850036
E19: 노인장기요양보험료 | G19: =경비집계!F11 -> 405109 | H19: =TRUNC(G19*12) -> 4861308 | I19: ="건강보험료×"&J19&"%" -> 건강보험료×12.81% | J19: ='고정)인적보험료'!M12 -> 12.81 | K19: =경비집계!F11 -> 405109 | L19: =K19-G19 -> 0 | N19: =H19*3 -> 14583924
E20: 임금채권보장보험료 | G20: =경비집계!F12 -> 53511 | H20: =TRUNC(G20*12) -> 642132 | I20: ="(기본급+제수당+상여금)×"&J20&"%" -> (기본급+제수당+상여금)×0.06% | J20: ='고정)인적보험료'!M13 -> 0.06 | K20: =경비집계!F12 -> 53511 | L20: =K20-G20 -> 0
E21: 석면피해구제분담금 | G21: =경비집계!F13 -> 3554 | H21: =TRUNC(G21*12) -> 42648 | I21: ="(기본급+제수당+상여금)×"&J21&"%" -> (기본급+제수당+상여금)×0.004% | J21: ='고정)인적보험료'!M14 -> 0.004 | K21: =경비집계!F13 -> 3554 | L21: =K21-G21 -> 0
C22: 복리후생비 | G22: =경비집계!F15 -> 4869242 | H22: =TRUNC(G22*12) -> 58430904 | K22: =경비집계!F15 -> 4869242 | L22: =K22-G22 -> 0
C23: 안전관리비 | G23: =경비집계!F16 -> 1797591.5 | H23: =TRUNC(G23*12) -> 21571097 | K23: =경비집계!F16 -> 1797591.5 | L23: =K23-G23 -> 0
C24: 교육훈련비 | G24: =경비집계!F17 -> 167397 | H24: =TRUNC(G24*12) -> 2008764 | K24: =경비집계!F17 -> 167397 | L24: =K24-G24 -> 0
C25: 소모품비 | G25: =경비집계!F18 -> 627434 | H25: =TRUNC(G25*12) -> 7529208 | K25: =경비집계!F18 -> 627434 | L25: =K25-G25 -> 0
C26: 출장여비 | G26: =경비집계!F19 -> 95661 | H26: =TRUNC(G26*12) -> 1147932 | K26: =경비집계!F19 -> 95661 | L26: =K26-G26 -> 0
C27: 통신 및 우편비 | G27: =경비집계!F20 -> 173066 | H27: =TRUNC(G27*12) -> 2076792 | K27: =경비집계!F20 -> 173066 | L27: =K27-G27 -> 0
C28: 계 | G28: =SUM(G15:G27) -> 17198307 | H28: =SUM(H15:H27) -> 206379689 | I28: =경비집계!$A$1&"참조" -> [ 표 : 16 ] 참조 | K28: =경비집계!F22 -> 17198307 | L28: =K28-G28 -> 0
B29: 순용역원가 | G29: =SUM(G14,G28) -> 1.1384301e+08 | H29: =TRUNC(G29*12) -> 1366116113 | I29: 인건비+경비
B30: ="일반관리비("&J30&"%)" -> 일반관리비(9%) | G30: =TRUNC(G29*$J$30%,0) -> 10245870 | H30: =TRUNC(G30*12) -> 122950440 | I30: ="순용역원가×"&J30&"%" -> 순용역원가×9% | J30: 9 | K30: =일반관리비!F10 -> 10245870 | L30: =K30-G30 -> 0
B31: ="이윤("&J31&"%)" -> 이윤(10%) | G31: =TRUNC((SUM(G14,G28,G30))*$J$31%,0) -> 12408887 | H31: =TRUNC(G31*12) -> 148906644 | I31: ="(순용역원가+일반관리비)×"&J31&"%" -> (순용역원가+일반관리비)×10% | J31: =용역원가집계!H5 -> 10 | K31: =이윤!G10 -> 12408887 | L31: =K31-G31 -> 0
B32: 용역원가 | G32: =SUM(G29:G31) -> 1.3649777e+08 | H32: =TRUNC(G32*12) -> 1637973197 | I32: 순용역원가+일.관+이윤
B33: 부가가치세(10%) | G33: =TRUNC((G32)*10%,0) -> 13649776 | H33: =TRUNC(G33*12) -> 163797312 | I33: 용역원가×10%
B34: 고정비 운영원가 | G34: =SUM(G32:G33) -> 1.5014754e+08 | H34: =TRUNC(G34*12) -> 1801770509 | I34: 용역원가+부가가치세 | N34: =H34*3 -> 5405311527
A35: 변 동 비 | B35: 변동비부문 | C35: 소모자재비 | G35: =경비집계!F23 -> 2250000 | H35: ='변동)소모자재비'!H13 -> 27000000 | K35: =경비집계!F23 -> 2250000 | L35: =K35-G35 -> 0
C36: 수선유지비 | G36: ='변동)수선유지비'!AE31 -> 49653333 | H36: ='변동)수선유지비'!AE30 -> 595840000 | K36: =경비집계!F24 -> 52986666 | L36: =K36-G36 -> 3333333
C37: 측정검사수수료 | G37: =경비집계!F25 -> 150263 | H37: ='변동)측정검사수수료'!H12 -> 1803166 | K37: =경비집계!F25 -> 150263 | L37: =K37-G37 -> 0
C38: 안전점검대행비 | G38: =경비집계!F26 -> 2440000 | H38: ='변동)안전점검대행비'!H14 -> 29280000 | K38: =경비집계!F26 -> 2440000 | L38: =K38-G38 -> 0
C39: 차량유지비 | G39: =경비집계!F27 -> 4939000 | H39: ='변동)차량유지비'!H15 -> 59268000 | K39: =경비집계!F27 -> 4939000 | L39: =K39-G39 -> 0
C40: 보안관리비 | G40: =경비집계!F28 -> 520000 | H40: ='변동)보안관리비'!H11 -> 6240000 | K40: =경비집계!F28 -> 520000 | L40: =K40-G40 -> 0
C41: 수집운반비 | G41: =경비집계!F29 -> 5808711 | H41: ='변동)수집운반비'!E12 -> 69704532 | I41: 부가세법 제26조, 동법 시행령 제35조 참조 | K41: =경비집계!F29 -> 5808711 | L41: =K41-G41 -> 0
...

Sheet 인건비집계
A1: ="[ 표 : "&U1&" ] " -> [ 표 : 5 ] | U1: ='용역원가(26년)'!J1+1 -> 5
A2: 인건비집계표
T4: 단위 : 원/월
A5: 구 분 | B5: 직 책 명 | D5: 직 종 명 | F5: 기본급 | I5: 제수당 | L5: 상여금 | O5: 퇴직급여충당금 | R5: 합 계 | U5: 비 고
F6: 단위(1인)당 인건비 | G6: 작업 인원 | H6: 금 액 | I6: 단위(1인)당 인건비 | J6: 작업 인원 | K6: 금 액 | L6: 단위(1인)당 인건비 | M6: 작업 인원 | N6: 금 액 | O6: 단위(1인)당 인건비 | P6: 작업 인원 | Q6: 금 액 | R6: 단위(1인)당 인건비 | S6: 작업 인원 | T6: 금 액
F7: 주 1) | G7: 주 2) | I7: 주 1) | J7: 주 2) | L7: 주 1) | M7: 주 2) | O7: 주 1) | P7: 주 2)
A8: =IF(월기본급!A8="","",월기본급!A8) -> 관리팀 | B8: =IF(월기본급!B8="","",월기본급!B8) -> 관리소장 | D8: =IF(월기본급!D8="","",월기본급!D8) -> 고급기술자 | F8: =단위당인건비!E8 -> 3145125 | G8: =투입인원!F8 -> 1 | H8: =TRUNC(G8*F8) -> 3145125 | I8: =단위당인건비!E12 -> 241000 | J8: =G8 -> 1 | K8: =TRUNC(J8*I8) -> 241000 | L8: =단위당인건비!E13 -> 1048375 | M8: =J8 -> 1 | N8: =TRUNC(M8*L8) -> 1048375 | O8: =단위당인건비!E14 -> 369541 | P8: =M8 -> 1 | Q8: =TRUNC(P8*O8) -> 369541 | R8: =SUM(F8,I8,L8,O8) -> 4804041 | S8: =P8 -> 1 | T8: =TRUNC(S8*R8) -> 4804041 | X8: =A8 -> 관리팀 | Y8: =B8 -> 관리소장 | Z8: 원/월 | AA8: =S8 -> 1 | AB8: =R8 -> 4804041 | AC8: =T8 -> 4804041
A9: =IF(월기본급!A9="","",월기본급!A9) -> 관리팀 | B9: =IF(월기본급!B9="","",월기본급!B9) -> 관리팀장 | D9: =IF(월기본급!D9="","",월기본급!D9) -> 고급기술자 | F9: =단위당인건비!E30 -> 3145125 | G9: =투입인원!F9 -> 1 | H9: =TRUNC(G9*F9) -> 3145125 | I9: =단위당인건비!E34 -> 761560 | J9: =G9 -> 1 | K9: =TRUNC(J9*I9) -> 761560 | L9: =단위당인건비!E35 -> 1048375 | M9: =J9 -> 1 | N9: =TRUNC(M9*L9) -> 1048375 | O9: =단위당인건비!E36 -> 412921 | P9: =M9 -> 1 | Q9: =TRUNC(P9*O9) -> 412921 | R9: =SUM(F9,I9,L9,O9) -> 5367981 | S9: =P9 -> 1 | T9: =TRUNC(S9*R9) -> 5367981 | X9: =A9 -> 관리팀 | Y9: =B9 -> 관리팀장 | Z9: 원/월 | AA9: =S9 -> 1 | AB9: =R9 -> 5367981 | AC9: =T9 -> 5367981
A10: =IF(월기본급!A10="","",월기본급!A10) -> 관리팀 | B10: =IF(월기본급!B10="","",월기본급!B10) -> 관리팀원 | D10: =IF(월기본급!D10="","",월기본급!D10) -> 초급숙련기술자 | F10: =단위당인건비!E228 -> 1966517 | G10: =투입인원!F10 -> 1 | H10: =TRUNC(G10*F10) -> 1966517 | I10: =단위당인건비!E232 -> 476148 | J10: =G10 -> 1 | K10: =TRUNC(J10*I10) -> 476148 | L10: =단위당인건비!E233 -> 655505 | M10: =J10 -> 1 | N10: =TRUNC(M10*L10) -> 655505 | O10: =단위당인건비!E234 -> 258180 | P10: =M10 -> 1 | Q10: =TRUNC(P10*O10) -> 258180 | R10: =SUM(F10,I10,L10,O10) -> 3356350 | S10: =P10 -> 1 | T10: =TRUNC(S10*R10) -> 3356350
A11: =IF(월기본급!A11="","",월기본급!A11) -> 운영팀 | B11: =IF(월기본급!B11="","",월기본급!B11) -> 전기팀장 | D11: =IF(월기본급!D11="","",월기본급!D11) -> 중급기술자 | F11: =단위당인건비!E52 -> 2641455 | G11: =투입인원!F11 -> 2 | H11: =TRUNC(G11*F11) -> 5282910 | I11: =단위당인건비!E56 -> 639584 | J11: =G11 -> 2 | K11: =TRUNC(J11*I11) -> 1279168 | L11: =단위당인건비!E57 -> 880485 | M11: =J11 -> 2 | N11: =TRUNC(M11*L11) -> 1760970 | O11: =단위당인건비!E58 -> 346793 | P11: =M11 -> 2 | Q11: =TRUNC(P11*O11) -> 693586 | R11: =SUM(F11,I11,L11,O11) -> 4508317 | S11: =P11 -> 2 | T11: =TRUNC(S11*R11) -> 9016634 | X11: =A11 -> 운영팀 | Y11: =B11 -> 전기팀장 | Z11: 원/월 | AA11: =S11 -> 2 | AB11: =R11 -> 4508317 | AC11: =T11 -> 9016634
A12: =IF(월기본급!A12="","",월기본급!A12) -> 운영팀 | B12: =IF(월기본급!B12="","",월기본급!B12) -> 기계팀장 | D12: =IF(월기본급!D12="","",월기본급!D12) -> 중급기술자 | F12: =단위당인건비!E74 -> 2641455 | G12: =투입인원!F12 -> 2 | H12: =TRUNC(G12*F12) -> 5282910 | I12: =단위당인건비!E78 -> 639584 | J12: =G12 -> 2 | K12: =TRUNC(J12*I12) -> 1279168 | L12: =단위당인건비!E79 -> 880485 | M12: =J12 -> 2 | N12: =TRUNC(M12*L12) -> 1760970 | O12: =단위당인건비!E80 -> 346793 | P12: =M12 -> 2 | Q12: =TRUNC(P12*O12) -> 693586 | R12: =SUM(F12,I12,L12,O12) -> 4508317 | S12: =P12 -> 2 | T12: =TRUNC(S12*R12) -> 9016634 | X12: =A12 -> 운영팀 | Y12: =B12 -> 기계팀장 | Z12: 원/월 | AA12: =S12 -> 2 | AB12: =R12 -> 4508317 | AC12: =T12 -> 9016634
A13: =IF(월기본급!A13="","",월기본급!A13) -> 운영팀 | B13: =IF(월기본급!B13="","",월기본급!B13) -> 전기담당 | D13: =IF(월기본급!D13="","",월기본급!D13) -> 초급기술자 | F13: =단위당인건비!E96 -> 2327017 | G13: =투입인원!F13 -> 2 | H13: =TRUNC(G13*F13) -> 4654034 | I13: =단위당인건비!E100 -> 563459 | J13: =G13 -> 2 | K13: =TRUNC(J13*I13) -> 1126918 | L13: =단위당인건비!E101 -> 775672 | M13: =J13 -> 2 | N13: =TRUNC(M13*L13) -> 1551344 | O13: =단위당인건비!E102 -> 305512 | P13: =M13 -> 2 | Q13: =TRUNC(P13*O13) -> 611024 | R13: =SUM(F13,I13,L13,O13) -> 3971660 | S13: =P13 -> 2 | T13: =TRUNC(S13*R13) -> 7943320 | X13: =A13 -> 운영팀 | Y13: =B13 -> 전기담당 | Z13: 원/월 | AA13: =S13 -> 2 | AB13: =R13 -> 3971660 | AC13: =T13 -> 7943320
A14: =IF(월기본급!A14="","",월기본급!A14) -> 운영팀 | B14: =IF(월기본급!B14="","",월기본급!B14) -> 기계담당 | D14: =IF(월기본급!D14="","",월기본급!D14) -> 초급기술자 | F14: =단위당인건비!E118 -> 2327017 | G14: =투입인원!F14 -> 2 | H14: =TRUNC(G14*F14) -> 4654034 | I14: =단위당인건비!E122 -> 563459 | J14: =G14 -> 2 | K14: =TRUNC(J14*I14) -> 1126918 | L14: =단위당인건비!E123 -> 775672 | M14: =J14 -> 2 | N14: =TRUNC(M14*L14) -> 1551344 | O14: =단위당인건비!E124 -> 305512 | P14: =M14 -> 2 | Q14: =TRUNC(P14*O14) -> 611024 | R14: =SUM(F14,I14,L14,O14) -> 3971660 | S14: =P14 -> 2 | T14: =TRUNC(S14*R14) -> 7943320 | X14: =A14 -> 운영팀 | Y14: =B14 -> 기계담당 | Z14: 원/월 | AA14: =S14 -> 2 | AB14: =R14 -> 3971660 | AC14: =T14 -> 7943320
A15: =IF(월기본급!A15="","",월기본급!A15) -> 운영팀 | B15: =IF(월기본급!B15="","",월기본급!B15) -> 전기담당 | D15: =IF(월기본급!D15="","",월기본급!D15) -> 고급숙련기술자 | F15: =단위당인건비!E140 -> 2515878 | G15: =투입인원!F15 -> 1 | H15: =TRUNC(G15*F15) -> 2515878 | I15: =단위당인건비!E144 -> 609184 | J15: =G15 -> 1 | K15: =TRUNC(J15*I15) -> 609184 | L15: =단위당인건비!E145 -> 838626 | M15: =J15 -> 1 | N15: =TRUNC(M15*L15) -> 838626 | O15: =단위당인건비!E146 -> 330307 | P15: =M15 -> 1 | Q15: =TRUNC(P15*O15) -> 330307 | R15: =SUM(F15,I15,L15,O15) -> 4293995 | S15: =P15 -> 1 | T15: =TRUNC(S15*R15) -> 4293995 | X15: =A15 -> 운영팀 | Y15: =B15 -> 전기담당 | Z15: 원/월 | AA15: =S15 -> 1 | AB15: =R15 -> 4293995 | AC15: =T15 -> 4293995
A16: =IF(월기본급!A16="","",월기본급!A16) -> 운영팀 | B16: =IF(월기본급!B16="","",월기본급!B16) -> 기계담당 | D16: =IF(월기본급!D16="","",월기본급!D16) -> 고급숙련기술자 | F16: =단위당인건비!E162 -> 2515878 | G16: =투입인원!F16 -> 1 | H16: =TRUNC(G16*F16) -> 2515878 | I16: =단위당인건비!E144 -> 609184 | J16: =G16 -> 1 | K16: =TRUNC(J16*I16) -> 609184 | L16: =단위당인건비!E167 -> 838626 | M16: =J16 -> 1 | N16: =TRUNC(M16*L16) -> 838626 | O16: =단위당인건비!E168 -> 330307 | P16: =M16 -> 1 | Q16: =TRUNC(P16*O16) -> 330307 | R16: =SUM(F16,I16,L16,O16) -> 4293995 | S16: =P16 -> 1 | T16: =TRUNC(S16*R16) -> 4293995 | X16: =A16 -> 운영팀 | Y16: =B16 -> 기계담당 | Z16: 원/월 | AA16: =S16 -> 1 | AB16: =R16 -> 4293995 | AC16: =T16 -> 4293995
A17: =IF(월기본급!A17="","",월기본급!A17) -> 운영팀 | B17: =IF(월기본급!B17="","",월기본급!B17) -> 전기담당 | D17: =IF(월기본급!D17="","",월기본급!D17) -> 중급숙련기술자 | F17: =단위당인건비!E184 -> 2238540 | G17: =투입인원!F17 -> 2 | H17: =TRUNC(G17*F17) -> 4477080 | I17: =단위당인건비!E188 -> 542034 | J17: =G17 -> 2 | K17: =TRUNC(J17*I17) -> 1084068 | L17: =단위당인건비!E189 -> 746180 | M17: =J17 -> 2 | N17: =TRUNC(M17*L17) -> 1492360 | O17: =단위당인건비!E190 -> 293896 | P17: =M17 -> 2 | Q17: =TRUNC(P17*O17) -> 587792 | R17: =SUM(F17,I17,L17,O17) -> 3820650 | S17: =P17 -> 2 | T17: =TRUNC(S17*R17) -> 7641300 | X17: =A17 -> 운영팀 | Y17: =B17 -> 전기담당 | Z17: 원/월 | AA17: =S17 -> 2 | AB17: =R17 -> 3820650 | AC17: =T17 -> 7641300
A18: =IF(월기본급!A18="","",월기본급!A18) -> 운영팀 | B18: =IF(월기본급!B18="","",월기본급!B18) -> 기계담당 | D18: =IF(월기본급!D18="","",월기본급!D18) -> 중급숙련기술자 | F18: =단위당인건비!E206 -> 2238540 | G18: =투입인원!F18 -> 2 | H18: =TRUNC(G18*F18) -> 4477080 | I18: =단위당인건비!E210 -> 542034 | J18: =G18 -> 2 | K18: =TRUNC(J18*I18) -> 1084068 | L18: =단위당인건비!E211 -> 746180 | M18: =J18 -> 2 | N18: =TRUNC(M18*L18) -> 1492360 | O18: =단위당인건비!E212 -> 293896 | P18: =M18 -> 2 | Q18: =TRUNC(P18*O18) -> 587792 | R18: =SUM(F18,I18,L18,O18) -> 3820650 | S18: =P18 -> 2 | T18: =TRUNC(S18*R18) -> 7641300 | X18: =A18 -> 운영팀 | Y18: =B18 -> 기계담당 | Z18: 원/월 | AA18: =S18 -> 2 | AB18: =R18 -> 3820650 | AC18: =T18 -> 7641300
A19: =IF(월기본급!A19="","",월기본급!A19) -> 운영팀 | B19: =IF(월기본급!B19="","",월기본급!B19) -> 전기담당 | D19: =IF(월기본급!D19="","",월기본급!D19) -> 초급숙련기술자 | F19: =단위당인건비!E250 -> 1966517 | G19: =투입인원!F19 -> 1 | H19: =TRUNC(G19*F19) -> 1966517 | I19: =단위당인건비!E254 -> 476148 | J19: =G19 -> 1 | K19: =TRUNC(J19*I19) -> 476148 | L19: =단위당인건비!E255 -> 655505 | M19: =J19 -> 1 | N19: =TRUNC(M19*L19) -> 655505 | O19: =단위당인건비!E256 -> 258180 | P19: =M19 -> 1 | Q19: =TRUNC(P19*O19) -> 258180 | R19: =SUM(F19,I19,L19,O19) -> 3356350 | S19: =P19 -> 1 | T19: =TRUNC(S19*R19) -> 3356350
A20: =IF(월기본급!A20="","",월기본급!A20) -> 운영팀 | B20: =IF(월기본급!B20="","",월기본급!B20) -> 기계담당 | D20: =IF(월기본급!D20="","",월기본급!D20) -> 초급숙련기술자 | F20: =단위당인건비!E272 -> 1966517 | G20: =투입인원!F20 -> 1 | H20: =TRUNC(G20*F20) -> 1966517 | I20: =단위당인건비!E276 -> 476148 | J20: =G20 -> 1 | K20: =TRUNC(J20*I20) -> 476148 | L20: =단위당인건비!E277 -> 655505 | M20: =J20 -> 1 | N20: =TRUNC(M20*L20) -> 655505 | O20: =단위당인건비!E278 -> 258180 | P20: =M20 -> 1 | Q20: =TRUNC(P20*O20) -> 258180 | R20: =SUM(F20,I20,L20,O20) -> 3356350 | S20: =P20 -> 1 | T20: =TRUNC(S20*R20) -> 3356350
A21: =IF(월기본급!A21="","",월기본급!A21) -> 환경팀 | B21: =IF(월기본급!B21="","",월기본급!B21) -> 환경팀장 | D21: =IF(월기본급!D21="","",월기본급!D21) -> 초급숙련기술자 | F21: =단위당인건비!E294 -> 1966517 | G21: =투입인원!F21 -> 1 | H21: =TRUNC(G21*F21) -> 1966517 | I21: =단위당인건비!E298 -> 476148 | J21: =G21 -> 1 | K21: =TRUNC(J21*I21) -> 476148 | L21: =단위당인건비!E299 -> 655505 | M21: =J21 -> 1 | N21: =TRUNC(M21*L21) -> 655505 | O21: =단위당인건비!E300 -> 258180 | P21: =M21 -> 1 | Q21: =TRUNC(P21*O21) -> 258180 | R21: =SUM(F21,I21,L21,O21) -> 3356350 | S21: =P21 -> 1 | T21: =TRUNC(S21*R21) -> 3356350
A22: =IF(월기본급!A22="","",월기본급!A22) -> 환경팀 | B22: =IF(월기본급!B22="","",월기본급!B22) -> 환경팀원 | D22: =IF(월기본급!D22="","",월기본급!D22) -> 단순노무종사원 | F22: =단위당인건비!E316 -> 1743130 | G22: =투입인원!F22 -> 2 | H22: =TRUNC(G22*F22) -> 3486260 | I22: =단위당인건비!E320 -> 422081 | J22: =G22 -> 2 | K22: =TRUNC(J22*I22) -> 844162 | L22: =단위당인건비!E321 -> 581043 | M22: =J22 -> 2 | N22: =TRUNC(M22*L22) -> 1162086 | O22: =단위당인건비!E322 -> 228854 | P22: =M22 -> 2 | Q22: =TRUNC(P22*O22) -> 457708 | R22: =SUM(F22,I22,L22,O22) -> 2975108 | S22: =P22 -> 2 | T22: =TRUNC(S22*R22) -> 5950216 | X22: =A22 -> 환경팀 | Y22: =B22 -> 환경팀원 | Z22: 원/월 | AA22: =S22 -> 2 | AB22: =R22 -> 2975108 | AC22: =T22 -> 5950216
A23: =IF(월기본급!A23="","",월기본급!A23) -> 운반팀 | B23: =IF(월기본급!B23="","",월기본급!B23) -> 운전원 | D23: =IF(월기본급!D23="","",월기본급!D23) -> 초급숙련기술자 | F23: =단위당인건비!E338 -> 1966517 | G23: =투입인원!F23 -> 1 | H23: =TRUNC(G23*F23) -> 1966517 | I23: =단위당인건비!E342 -> 476148 | J23: =G23 -> 1 | K23: =TRUNC(J23*I23) -> 476148 | L23: =단위당인건비!E343 -> 655505 | M23: =J23 -> 1 | N23: =TRUNC(M23*L23) -> 655505 | O23: =단위당인건비!E344 -> 258180 | P23: =M23 -> 1 | Q23: =TRUNC(P23*O23) -> 258180 | R23: =SUM(F23,I23,L23,O23) -> 3356350 | S23: =P23 -> 1 | T23: =TRUNC(S23*R23) -> 3356350
A24: =IF(월기본급!A24="","",월기본급!A24) -> 운반팀 | B24: =IF(월기본급!B24="","",월기본급!B24) -> 운반팀원 | D24: =IF(월기본급!D24="","",월기본급!D24) -> 단순노무종사원 | F24: =단위당인건비!E360 -> 1743130 | G24: =투입인원!F24 -> 2 | H24: =TRUNC(G24*F24) -> 3486260 | I24: =단위당인건비!E364 -> 422081 | J24: =G24 -> 2 | K24: =TRUNC(J24*I24) -> 844162 | L24: =단위당인건비!E365 -> 581043 | M24: =J24 -> 2 | N24: =TRUNC(M24*L24) -> 1162086 | O24: =단위당인건비!E366 -> 228854 | P24: =M24 -> 2 | Q24: =TRUNC(P24*O24) -> 457708 | R24: =SUM(F24,I24,L24,O24) -> 2975108 | S24: =P24 -> 2 | T24: =TRUNC(S24*R24) -> 5950216
A25: 계 | G25: =SUM(G8:G24) -> 25 | H25: =SUM(H8:H24) -> 56955159 | J25: =SUM(J8:J24) -> 25 | K25: =SUM(K8:K24) -> 13270300 | M25: =SUM(M8:M24) -> 25 | N25: =SUM(N8:N24) -> 18985047 | P25: =SUM(P8:P24) -> 25 | Q25: =SUM(Q8:Q24) -> 7434196 | S25: =SUM(S8:S24) -> 25 | T25: =SUM(T8:T24) -> 96644702 | AA25: =SUM(AA8:AA22) -> 18 | AC25: =SUM(AC8:AC22) -> 73912736
A26: ="주 1) 단위(1인당)인건비 : "&단위당인건비!A1&단위당인건비!A2&" 참조" -> 주 1) 단위(1인당)인건비 : [ 표 : 7 ] 직책별 단위(1인)당 인건비산출표 참조
A27: =" 2) 작업인원 : "&투입인원!A1&투입인원!A2&" 참조" -> 2) 작업인원 : [ 표 : 12 ] 적용직종 및 근무형태 참조

Sheet 제수당집계
A1: ="[ 표 : "&U1&" ] " -> [ 표 : 6 ] | U1: =인건비집계!U1+1 -> 6
A2: 제수당집계표
T4: 단위 : 원/월
A5: 구 분 | B5: 직 책 명 | D5: 직 종 명 | F5: 년차수당 | I5: 연장근로수당 | L5: 휴일근로수당 | O5: 휴일근로수당 | R5: 합 계
F6: 단위(1인)당 제수당 | G6: 작업 인원 | H6: 금 액 | I6: 단위(1인)당 제수당 | J6: 작업 인원 | K6: 금 액 | L6: 단위(1인)당 제수당 | M6: 작업 인원 | N6: 금 액 | O6: 단위(1인)당 제경비 | P6: 작업 인원 | Q6: 금 액 | R6: 단위(1인)당 제경비 | S6: 작업 인원 | T6: 금 액
F7: 주 1) | G7: 주 2) | I7: 주 1) | J7: 주 2) | L7: 주 1) | M7: 주 2) | O7: 주 1) | P7: 주 2)
A8: =IF(월기본급!A8="","",월기본급!A8) -> 관리팀 | B8: =IF(월기본급!B8="","",월기본급!B8) -> 관리소장 | D8: =IF(월기본급!D8="","",월기본급!D8) -> 고급기술자 | F8: =단위당인건비!E9 -> 241000 | G8: =투입인원!F8 -> 1 | H8: =TRUNC(G8*F8) -> 241000 | I8: =단위당인건비!E10 -> 0 | J8: =G8 -> 1 | K8: =TRUNC(J8*I8) -> 0 | L8: =단위당인건비!E11 -> 0 | M8: =J8 -> 1 | N8: =TRUNC(M8*L8) -> 0 | P8: =M8 -> 1 | Q8: =TRUNC(P8*O8) -> 0 | R8: =SUM(F8,I8,L8,O8) -> 241000 | S8: =P8 -> 1 | T8: =TRUNC(S8*R8) -> 241000
A9: =IF(월기본급!A9="","",월기본급!A9) -> 관리팀 | B9: =IF(월기본급!B9="","",월기본급!B9) -> 관리팀장 | D9: =IF(월기본급!D9="","",월기본급!D9) -> 고급기술자 | F9: =단위당인건비!E31 -> 241000 | G9: =투입인원!F9 -> 1 | H9: =TRUNC(G9*F9) -> 241000 | I9: =단위당인건비!E32 -> 0 | J9: =G9 -> 1 | K9: =TRUNC(J9*I9) -> 0 | L9: =단위당인건비!E33 -> 520560 | M9: =J9 -> 1 | N9: =TRUNC(M9*L9) -> 520560 | P9: =M9 -> 1 | Q9: =TRUNC(P9*O9) -> 0 | R9: =SUM(F9,I9,L9,O9) -> 761560 | S9: =P9 -> 1 | T9: =TRUNC(S9*R9) -> 761560
A10: =IF(월기본급!A10="","",월기본급!A10) -> 관리팀 | B10: =IF(월기본급!B10="","",월기본급!B10) -> 관리팀원 | D10: =IF(월기본급!D10="","",월기본급!D10) -> 초급숙련기술자 | F10: =단위당인건비!E229 -> 150680 | G10: =투입인원!F10 -> 1 | H10: =TRUNC(G10*F10) -> 150680 | J10: =G10 -> 1 | L10: =단위당인건비!E231 -> 325468 | M10: =J10 -> 1 | N10: =TRUNC(M10*L10) -> 325468 | P10: =M10 -> 1 | R10: =SUM(F10,I10,L10,O10) -> 476148 | S10: =P10 -> 1 | T10: =TRUNC(S10*R10) -> 476148
A11: =IF(월기본급!A11="","",월기본급!A11) -> 운영팀 | B11: =IF(월기본급!B11="","",월기본급!B11) -> 전기팀장 | D11: =IF(월기본급!D11="","",월기본급!D11) -> 중급기술자 | F11: =단위당인건비!E53 -> 202400 | G11: =투입인원!F11 -> 2 | H11: =TRUNC(G11*F11) -> 404800 | I11: =단위당인건비!E54 -> 0 | J11: =G11 -> 2 | K11: =TRUNC(J11*I11) -> 0 | L11: =단위당인건비!E55 -> 437184 | M11: =J11 -> 2 | N11: =TRUNC(M11*L11) -> 874368 | P11: =M11 -> 2 | Q11: =TRUNC(P11*O11) -> 0 | R11: =SUM(F11,I11,L11,O11) -> 639584 | S11: =P11 -> 2 | T11: =TRUNC(S11*R11) -> 1279168
A12: =IF(월기본급!A12="","",월기본급!A12) -> 운영팀 | B12: =IF(월기본급!B12="","",월기본급!B12) -> 기계팀장 | D12: =IF(월기본급!D12="","",월기본급!D12) -> 중급기술자 | F12: =단위당인건비!E75 -> 202400 | G12: =투입인원!F12 -> 2 | H12: =TRUNC(G12*F12) -> 404800 | I12: =단위당인건비!E76 -> 0 | J12: =G12 -> 2 | K12: =TRUNC(J12*I12) -> 0 | L12: =단위당인건비!E77 -> 437184 | M12: =J12 -> 2 | N12: =TRUNC(M12*L12) -> 874368 | P12: =M12 -> 2 | Q12: =TRUNC(P12*O12) -> 0 | R12: =SUM(F12,I12,L12,O12) -> 639584 | S12: =P12 -> 2 | T12: =TRUNC(S12*R12) -> 1279168
A13: =IF(월기본급!A13="","",월기본급!A13) -> 운영팀 | B13: =IF(월기본급!B13="","",월기본급!B13) -> 전기담당 | D13: =IF(월기본급!D13="","",월기본급!D13) -> 초급기술자 | F13: =단위당인건비!E97 -> 178310 | G13: =투입인원!F13 -> 2 | H13: =TRUNC(G13*F13) -> 356620 | I13: =단위당인건비!E98 -> 0 | J13: =G13 -> 2 | K13: =TRUNC(J13*I13) -> 0 | L13: =단위당인건비!E99 -> 385149 | M13: =J13 -> 2 | N13: =TRUNC(M13*L13) -> 770298 | P13: =M13 -> 2 | Q13: =TRUNC(P13*O13) -> 0 | R13: =SUM(F13,I13,L13,O13) -> 563459 | S13: =P13 -> 2 | T13: =TRUNC(S13*R13) -> 1126918
A14: =IF(월기본급!A14="","",월기본급!A14) -> 운영팀 | B14: =IF(월기본급!B14="","",월기본급!B14) -> 기계담당 | D14: =IF(월기본급!D14="","",월기본급!D14) -> 초급기술자 | F14: =단위당인건비!E119 -> 178310 | G14: =투입인원!F14 -> 2 | H14: =TRUNC(G14*F14) -> 356620 | I14: =단위당인건비!E120 -> 0 | J14: =G14 -> 2 | K14: =TRUNC(J14*I14) -> 0 | L14: =단위당인건비!E121 -> 385149 | M14: =J14 -> 2 | N14: =TRUNC(M14*L14) -> 770298 | P14: =M14 -> 2 | Q14: =TRUNC(P14*O14) -> 0 | R14: =SUM(F14,I14,L14,O14) -> 563459 | S14: =P14 -> 2 | T14: =TRUNC(S14*R14) -> 1126918
A15: =IF(월기본급!A15="","",월기본급!A15) -> 운영팀 | B15: =IF(월기본급!B15="","",월기본급!B15) -> 전기담당 | D15: =IF(월기본급!D15="","",월기본급!D15) -> 고급숙련기술자 | F15: =단위당인건비!E141 -> 192780 | G15: =투입인원!F15 -> 1 | H15: =TRUNC(G15*F15) -> 192780 | I15: =단위당인건비!E142 -> 0 | J15: =G15 -> 1 | K15: =TRUNC(J15*I15) -> 0 | L15: =단위당인건비!E143 -> 416404 | M15: =J15 -> 1 | N15: =TRUNC(M15*L15) -> 416404 | P15: =M15 -> 1 | Q15: =TRUNC(P15*O15) -> 0 | R15: =SUM(F15,I15,L15,O15) -> 609184 | S15: =P15 -> 1 | T15: =TRUNC(S15*R15) -> 609184
A16: =IF(월기본급!A16="","",월기본급!A16) -> 운영팀 | B16: =IF(월기본급!B16="","",월기본급!B16) -> 기계담당 | D16: =IF(월기본급!D16="","",월기본급!D16) -> 고급숙련기술자 | F16: =단위당인건비!E163 -> 192780 | G16: =투입인원!F16 -> 1 | H16: =TRUNC(G16*F16) -> 192780 | I16: =단위당인건비!E164 -> 0 | J16: =G16 -> 1 | K16: =TRUNC(J16*I16) -> 0 | L16: =단위당인건비!E165 -> 416404 | M16: =J16 -> 1 | N16: =TRUNC(M16*L16) -> 416404 | P16: =M16 -> 1 | Q16: =TRUNC(P16*O16) -> 0 | R16: =SUM(F16,I16,L16,O16) -> 609184 | S16: =P16 -> 1 | T16: =TRUNC(S16*R16) -> 609184
A17: =IF(월기본급!A17="","",월기본급!A17) -> 운영팀 | B17: =IF(월기본급!B17="","",월기본급!B17) -> 전기담당 | D17: =IF(월기본급!D17="","",월기본급!D17) -> 중급숙련기술자 | F17: =단위당인건비!E185 -> 171530 | G17: =투입인원!F17 -> 2 | H17: =TRUNC(G17*F17) -> 343060 | I17: =단위당인건비!E186 -> 0 | J17: =G17 -> 2 | K17: =TRUNC(J17*I17) -> 0 | L17: =단위당인건비!E187 -> 370504 | M17: =J17 -> 2 | N17: =TRUNC(M17*L17) -> 741008 | P17: =M17 -> 2 | Q17: =TRUNC(P17*O17) -> 0 | R17: =SUM(F17,I17,L17,O17) -> 542034 | S17: =P17 -> 2 | T17: =TRUNC(S17*R17) -> 1084068
A18: =IF(월기본급!A18="","",월기본급!A18) -> 운영팀 | B18: =IF(월기본급!B18="","",월기본급!B18) -> 기계담당 | D18: =IF(월기본급!D18="","",월기본급!D18) -> 중급숙련기술자 | F18: =단위당인건비!E207 -> 171530 | G18: =투입인원!F18 -> 2 | H18: =TRUNC(G18*F18) -> 343060 | I18: =단위당인건비!E208 -> 0 | J18: =G18 -> 2 | K18: =TRUNC(J18*I18) -> 0 | L18: =단위당인건비!E209 -> 370504 | M18: =J18 -> 2 | N18: =TRUNC(M18*L18) -> 741008 | P18: =M18 -> 2 | Q18: =TRUNC(P18*O18) -> 0 | R18: =SUM(F18,I18,L18,O18) -> 542034 | S18: =P18 -> 2 | T18: =TRUNC(S18*R18) -> 1084068
A19: =IF(월기본급!A19="","",월기본급!A19) -> 운영팀 | B19: =IF(월기본급!B19="","",월기본급!B19) -> 전기담당 | D19: =IF(월기본급!D19="","",월기본급!D19) -> 초급숙련기술자 | F19: =단위당인건비!E251 -> 150680 | G19: =투입인원!F19 -> 1 | H19: =TRUNC(G19*F19) -> 150680 | I19: =단위당인건비!E252 -> 0 | J19: =G19 -> 1 | K19: =TRUNC(J19*I19) -> 0 | L19: =단위당인건비!E253 -> 325468 | M19: =J19 -> 1 | N19: =TRUNC(M19*L19) -> 325468 | P19: =M19 -> 1 | Q19: =TRUNC(P19*O19) -> 0 | R19: =SUM(F19,I19,L19,O19) -> 476148 | S19: =P19 -> 1 | T19: =TRUNC(S19*R19) -> 476148
A20: =IF(월기본급!A20="","",월기본급!A20) -> 운영팀 | B20: =IF(월기본급!B20="","",월기본급!B20) -> 기계담당 | D20: =IF(월기본급!D20="","",월기본급!D20) -> 초급숙련기술자 | F20: =단위당인건비!E273 -> 150680 | G20: =투입인원!F20 -> 1 | H20: =TRUNC(G20*F20) -> 150680 | J20: =G20 -> 1 | L20: =단위당인건비!E275 -> 325468 | M20: =J20 -> 1 | N20: =TRUNC(M20*L20) -> 325468 | P20: =M20 -> 1 | R20: =SUM(F20,I20,L20,O20) -> 476148 | S20: =P20 -> 1 | T20: =TRUNC(S20*R20) -> 476148
A21: =IF(월기본급!A21="","",월기본급!A21) -> 환경팀 | B21: =IF(월기본급!B21="","",월기본급!B21) -> 환경팀장 | D21: =IF(월기본급!D21="","",월기본급!D21) -> 초급숙련기술자 | F21: =단위당인건비!E295 -> 150680 | G21: =투입인원!F21 -> 1 | H21: =TRUNC(G21*F21) -> 150680 | J21: =G21 -> 1 | L21: =단위당인건비!E297 -> 325468 | M21: =J21 -> 1 | N21: =TRUNC(M21*L21) -> 325468 | P21: =M21 -> 1 | R21: =SUM(F21,I21,L21,O21) -> 476148 | S21: =P21 -> 1 | T21: =TRUNC(S21*R21) -> 476148
A22: =IF(월기본급!A22="","",월기본급!A22) -> 환경팀 | B22: =IF(월기본급!B22="","",월기본급!B22) -> 환경팀원 | D22: =IF(월기본급!D22="","",월기본급!D22) -> 단순노무종사원 | F22: =단위당인건비!E317 -> 133570 | G22: =투입인원!F22 -> 2 | H22: =TRUNC(G22*F22) -> 267140 | J22: =G22 -> 2 | L22: =단위당인건비!E319 -> 288511 | M22: =J22 -> 2 | N22: =TRUNC(M22*L22) -> 577022 | P22: =M22 -> 2 | R22: =SUM(F22,I22,L22,O22) -> 422081 | S22: =P22 -> 2 | T22: =TRUNC(S22*R22) -> 844162
A23: =IF(월기본급!A23="","",월기본급!A23) -> 운반팀 | B23: =IF(월기본급!B23="","",월기본급!B23) -> 운전원 | D23: =IF(월기본급!D23="","",월기본급!D23) -> 초급숙련기술자 | F23: =단위당인건비!E339 -> 150680 | G23: =투입인원!F23 -> 1 | H23: =TRUNC(G23*F23) -> 150680 | J23: =G23 -> 1 | L23: =단위당인건비!E341 -> 325468 | M23: =J23 -> 1 | N23: =TRUNC(M23*L23) -> 325468 | P23: =M23 -> 1 | R23: =SUM(F23,I23,L23,O23) -> 476148 | S23: =P23 -> 1 | T23: =TRUNC(S23*R23) -> 476148
A24: =IF(월기본급!A24="","",월기본급!A24) -> 운반팀 | B24: =IF(월기본급!B24="","",월기본급!B24) -> 운반팀원 | D24: =IF(월기본급!D24="","",월기본급!D24) -> 단순노무종사원 | F24: =단위당인건비!E361 -> 133570 | G24: =투입인원!F24 -> 2 | H24: =TRUNC(G24*F24) -> 267140 | I24: =단위당인건비!E274 -> 0 | J24: =G24 -> 2 | K24: =TRUNC(J24*I24) -> 0 | L24: =단위당인건비!E363 -> 288511 | M24: =J24 -> 2 | N24: =TRUNC(M24*L24) -> 577022 | P24: =M24 -> 2 | Q24: =TRUNC(P24*O24) -> 0 | R24: =SUM(F24,I24,L24,O24) -> 422081 | S24: =P24 -> 2 | T24: =TRUNC(S24*R24) -> 844162
A25: 계 | G25: =SUM(G8:G24) -> 25 | H25: =SUM(H8:H24) -> 4364200 | J25: =SUM(J8:J24) -> 25 | K25: =SUM(K8:K24) -> 0 | M25: =SUM(M8:M24) -> 25 | N25: =SUM(N8:N24) -> 8906100 | P25: =SUM(P8:P24) -> 25 | Q25: =SUM(Q8:Q15) -> 0 | S25: =SUM(S8:S24) -> 25 | T25: =SUM(T8:T24) -> 13270300
A26: ="주 1) 단위(1인당)인건비 : "&단위당인건비!A1&단위당인건비!A2&" 참조" -> 주 1) 단위(1인당)인건비 : [ 표 : 7 ] 직책별 단위(1인)당 인건비산출표 참조
A27: =" 2) 작업인원 : "&투입인원!A1&투입인원!A2&" 참조" -> 2) 작업인원 : [ 표 : 12 ] 적용직종 및 근무형태 참조

Sheet 단위당인건비
A1: ="[ 표 : "&I1&" ] " -> [ 표 : 7 ] | I1: =제수당집계!U1+1 -> 7
A2: 직책별 단위(1인)당 인건비산출표
A4: ="구분 : "&월기본급!$A$8&" 직책 : "&월기본급!$B$8&" 직종명 : "&월기본급!$D$8&"" -> 구분 : 관리팀 직책 : 관리소장 직종명 : 고급기술자 | H4: 단위 : 원/월 | I4: =월기본급!$H$8 -> 20.6 | J4: 월근로시간 | K4: 휴일
A5: 구 분 | E5: 금 액 | G5: 관 련 법 규 | H5: 비 고 | I5: 4 | J5: 상여 | K5: =근무일수!Q11 -> 1.8
A6: 통상일급 | E6: =TRUNC(E7*8,0) -> 192800 | H6: 주 1)
A7: 통상시간급 | E7: =TRUNC(월기본급!$G$8+(E13/209),0) -> 24100 | H7: 주 2)
A8: 기본급 | E8: =월기본급!$I$8 -> 3145125 | G8: =월기본급!$A$1&" 참조" -> [ 표 : 8 ] 참조 | H8: 주 3)
A9: 제 수 당 | C9: 년차수당 | E9: =TRUNC(E6*15/12,0) -> 241000 | G9: 근로기준법 제60조 | H9: 주 4)
C10: 연장근로수당 | E10: =TRUNC(E6*I10*150%) -> 0 | G10: 근로기준법 제56조 | H10: 주 5) | J10: 연장근로일수
C11: 휴일근로수당 | E11: =TRUNC(E6*I11*150%) -> 0 | G11: 근로기준법 제56조 | H11: 주 6) | J11: 휴일근로일수
C12: 소계 | E12: =SUM(E9:E11) -> 241000
A13: 상여금 | E13: =TRUNC(E8*$I$5/12,0) -> 1048375 | H13: 주 7)
A14: 퇴직급여충당금 | E14: =TRUNC(SUM(E8,E12,E13)/12,0) -> 369541 | G14: 근로자퇴직급여 보장법 제8조 | H14: 주 8)
A15: 계 | E15: =SUM(E8,E12,E13,E14) -> 4804041
A16: ="주 1) 통상일급 : 통상시간급 × 8시간" -> 주 1) 통상일급 : 통상시간급 × 8시간
A17: 2) 통상시간급 : 시간급+(상여금÷209시간) | N17: =192800*20.6 -> 3971680
A18: * 월근무일수 = [(8시간(일일근로시간)×5일+8시간(유휴근로시간)]÷7일(1주)×365일/12개월 ≒ 209시간
A19: =" 3) 기본급 : "&월기본급!$A$1&월기본급!$A$2&" 참조" -> 3) 기본급 : [ 표 : 8 ] 월(M/M)당기본급산출표 참조
A20: =" 4) 년차수당 : "&FIXED(E6,0)&"(통상일급) × 15일/년 ÷ 12개월" -> 4) 년차수당 : 192,800(통상일급) × 15일/년 ÷ 12개월
A21: =" 5) 연장근로수당 : "&FIXED(E6,0)&"(통상일급) × "&I10&"일(연장근로일수) × 150%" -> 5) 연장근로수당 : 192,800(통상일급) × 일(연장근로일수) × 150%
A22: =" 6) 휴일근로수당 : "&FIXED(E6,0)&"(통상일급) × "&I11&"일(휴일근로일수) × 150%" -> 6) 휴일근로수당 : 192,800(통상일급) × 일(휴일근로일수) × 150%
A23: =" 7) 상여금 : "&FIXED(E8,0)&"(기본급) × "&$I$5&"개월(년 "&$I$5*100&"% 적용) ÷ 12개월" -> 7) 상여금 : 3,145,125(기본급) × 4개월(년 400% 적용) ÷ 12개월
A24: =" 8) 퇴직급여충당금 : {"&FIXED(E8,0)&"(기본급)+"&FIXED(E12,0)&"(제수당)+"&FIXED(E13,0)&"(상여금)} ÷ 12개월" -> 8) 퇴직급여충당금 : {3,145,125(기본급)+241,000(제수당)+1,048,375(상여금)} ÷ 12개월
A26: ="구분 : "&월기본급!$A$9&" 직책 : "&월기본급!$B$9&" 직종명 : "&월기본급!$D$9&"" -> 구분 : 관리팀 직책 : 관리팀장 직종명 : 고급기술자 | H26: 단위 : 원/월 | I26: =월기본급!$H$9 -> 20.6 | J26: 월근로시간
A27: 구 분 | E27: 금 액 | G27: 관 련 법 규 | H27: 비 고
A28: 통상일급 | E28: =TRUNC(E29*8,0) -> 192800 | H28: 주 1)
A29: 통상시간급 | E29: =TRUNC(월기본급!$G$9+(E35/209),0) -> 24100 | H29: 주 2)
A30: 기본급 | E30: =월기본급!$I$9 -> 3145125 | G30: =월기본급!$A$1&" 참조" -> [ 표 : 8 ] 참조 | H30: 주 3)
A31: 제 수 당 | C31: 년차수당 | E31: =TRUNC(E28*15/12,0) -> 241000 | G31: 근로기준법 제60조 | H31: 주 4)
C32: 연장근로수당 | E32: =TRUNC(E28*I32*150%) -> 0 | G32: 근로기준법 제56조 | H32: 주 5) | J32: 연장근로일수
C33: 휴일근로수당 | E33: =TRUNC(E28*I33*150%) -> 520560 | G33: 근로기준법 제56조 | H33: 주 6) | I33: =$K$5 -> 1.8 | J33: 휴일근로일수
C34: 소계 | E34: =SUM(E31:E33) -> 761560
A35: 상여금 | E35: =TRUNC(E30*$I$5/12,0) -> 1048375 | H35: 주 7)
A36: 퇴직급여충당금 | E36: =TRUNC(SUM(E30,E34,E35)/12,0) -> 412921 | G36: 근로자퇴직급여 보장법 제8조 | H36: 주 8)
A37: 계 | E37: =SUM(E30,E34,E35,E36) -> 5367981
A38: ="주 1) 통상일급 : 통상시간급 × 8시간" -> 주 1) 통상일급 : 통상시간급 × 8시간
A39: 2) 통상시간급 : 시간급+(상여금÷209시간)
A40: * 월근무일수 = [(8시간(일일근로시간)×5일+8시간(유휴근로시간)]÷7일(1주)×365일/12개월 ≒ 209시간
A41: =" 3) 기본급 : "&월기본급!$A$1&월기본급!$A$2&" 참조" -> 3) 기본급 : [ 표 : 8 ] 월(M/M)당기본급산출표 참조
A42: =" 4) 년차수당 : "&FIXED(E28,0)&"(통상일급) × 15일/년 ÷ 12개월" -> 4) 년차수당 : 192,800(통상일급) × 15일/년 ÷ 12개월
...

Sheet 엔지니어노임
A1: ="[ 표 : "&L1&" ] " -> [ 표 : 10 ] | L1: =기본급추정!O1+1 -> 10 | N1: 엔지니어링기술자 등급별 일급(분개)단가표
A2: 엔지니어링기술자 등급별 M/D당 임율산출표
R3: (단위 : 원)
K4: 단위 : 원
A5: 구 분 | D5: 기계/설비 | E5: 전기 | F5: 정보통신 | G5: 건설 | H5: 환경 | I5: 원자력 | J5: 기타 | K5: 비 고 | N5: 구분 | P5: M/D당 임률(2023년) | Q5: 일급(분개)단가 | R5: 비고
N6: 기술사 | P6: 424902 | Q6: 220843 | R6: 엔지니어링기술자 평균임금(환경)
B7: 기술사 | D7: 445789 | E7: 431962 | F7: 417280 | G7: 432440 | H7: 424902 | I7: 539581 | J7: 400781 | N7: 특급기술자 | P7: 322680 | Q7: 167711
B8: 특급기술자 | D8: 367153 | E8: 325361 | F8: 310245 | G8: 335638 | H8: 322680 | I8: 450664 | J8: 325337 | N8: 고급기술자 | P8: 293753 | Q8: 152676
B9: 고급기술자 | D9: 313547 | E9: 285820 | F9: 281987 | G9: 282545 | H9: 293753 | I9: 361182 | J9: 280031 | N9: 중급기술자 | P9: 246709 | Q9: 128226
B10: 중급기술자 | D10: 266506 | E10: 268378 | F10: 254590 | G10: 261571 | H10: 246709 | I10: 324116 | J10: 228300 | N10: 초급기술자 | P10: 217342 | Q10: 112962
B11: 초급기술자 | D11: 228792 | E11: 224434 | F11: 218500 | G11: 205686 | H11: 217342 | I11: 267042 | J11: 202067 | N11: 고급숙련기술자 | P11: 234982 | Q11: 122130
B12: 고급숙련기술자 | D12: 273502 | E12: 283141 | F12: 232694 | G12: 240947 | H12: 234982 | I12: 324521 | J12: 250442 | N12: 중급숙련기술자 | P12: 209077 | Q12: 108667
B13: 중급숙련기술자 | D13: 207122 | E13: 211043 | F13: 202588 | G13: 220894 | H13: 209077 | I13: 301470 | J13: 201395 | N13: 초급숙련기술자 | P13: 183671 | Q13: 95462
B14: 초급숙련기술자 | D14: 185413 | E14: 181762 | F14: 175059 | G14: 186909 | H14: 183671 | I14: 201653 | J14: 166204 | N14: 단순노무종사원주1) | P14: 84618 | Q14: 84618 | R14: 중소기업중앙회
B15: 근무일수(일) | D15: 20.6 | E15: 20.6 | F15: 20.6 | G15: 20.6 | H15: 20.6 | I15: 20.6 | J15: 20.6 | N15: 주 1) 중소기업중앙회 : 본 평균 조사노임(일급)의 적용시점 : 2023. 1. 1.
A16: 주) 엔지니어링 기술자 등급별 일 노임단가(한국엔지니어링협회, 2023.01.01 시행)
B17: * 환경부문 : 대기관리, 수질관리, 소음·진동, 폐기물처리, 자연·토양환경이 있음

Sheet 월기본급
A1: ="[ 표 : "&K1&" ] " -> [ 표 : 8 ] | K1: =단위당인건비!I1+1 -> 8
A2: 월(M/M)당기본급산출표
J4: 단위 : 원/월
A5: 구 분 | B5: 직 책 명 | D5: 직 종 명 | F5: 일(M/D)당 기본급 | G5: 시간(M/HR)당 기본급 | H5: 월평균 근무일수 | I5: 월(M/M)당 기본급 | J5: 비 고 | K5: =ROUND((8*5+8)/7*365/12,0) -> 209 | P5: 직종번호
F7: 주 1) | G7: 주 2) | H7: 주 3) | I7: 주 4)
A8: =IF(투입인원!A8="","",투입인원!A8) -> 관리팀 | B8: =IF(투입인원!B8="","",투입인원!B8) -> 관리소장 | D8: =IF(투입인원!D8="","",투입인원!D8) -> 고급기술자 | F8: =HLOOKUP(D8,기본급추정!$5:$11,5,FALSE) -> 152676 | G8: =TRUNC(F8/8) -> 19084 | H8: 20.6 | I8: =TRUNC(F8*H8) -> 3145125 | K8: =G8*209 -> 3988556 | L8: =F8/8*209 -> 3988660.5 | P8: =CONCATENATE("제-",VLOOKUP(D8,#REF!,4,FALSE),"번") -> #REF! | R8: =152676*20.6 -> 3145125.6
A9: =IF(투입인원!A9="","",투입인원!A9) -> 관리팀 | B9: =IF(투입인원!B9="","",투입인원!B9) -> 관리팀장 | D9: =IF(투입인원!D9="","",투입인원!D9) -> 고급기술자 | F9: =HLOOKUP(D9,기본급추정!$5:$11,5,FALSE) -> 152676 | G9: =TRUNC(F9/8) -> 19084 | H9: =H8 -> 20.6 | I9: =TRUNC(F9*H9) -> 3145125 | K9: =G9*209 -> 3988556 | L9: =F9/8*209 -> 3988660.5 | P9: =CONCATENATE("제-",VLOOKUP(D9,#REF!,4,FALSE),"번") -> #REF!
